Workbook

Sheet LCL+LOCAL - IMPORT (2)
A1: LCL + LOCAL
A2: No | B2: INVOICE No | C2: AWB,B/L No | D2: DATE | E2: KGS | F2: KGS OF BL | G2: CBM | H2: FREIGHT AIR | I2: FREIGHT SEA | J2: TRUCKING FEE | K2: SERVICE FEE | L2: CFS | M2: CIC | N2: THC | O2: D/O | P2: HANDLING | Q2: STORAGE | R2: CSHT | S2: INCURRED | T2: VAT PASS THROUGH | U2: CLEARING EXPENSE | V2: TOTAL | W2: PORT | X2: No | Y2: INVOICE No | Z2: DATE | AA2: FREIGHT AIR PER P/L | AB2: FREIGHT SEA PER P/L | AC2: TRUCKING FEE | AD2: SERVICE FEE | AE2: CFS | AF2: CIC | AG2: THC | AH2: D/O | AI2: HANDLING | AJ2: STORAGE | AK2: CSHT | AL2: INCURRED | AM2: VAT PASS THROUGH | AN2: CLEARING EXPENSE PER P/L | AO2: TOTAL | AP2: PORT | AR2: Biển số xe | AS2: Nơi đi - Nơi đến
A3: PS254498 | B3: IE20250716073 | C3: SJS5071963 | D3: 45861 | E3: 49 | F3: 49 | J3: =+IF(F3<=50,1060000, IF(F3<=200, 1210000, IF(F3<=500, 1230000, IF(F3<=1000, 1440000, IF(F3<=2000, 1990000, IF(F3>2000, 1990000+(F3-2000)*1464)))))) -> 1060000 | K3: 990000 | Q3: 162000 | T3: =SUM(J3:S3)*0.08 -> 176960 | U3: =SUM(J3:T3) -> 2388960 | V3: =U3 -> 2388960 | W3: TCS | X3: =A3 -> PS254498 | Y3: =B3 -> IE20250716073 | Z3: =D3 -> 45861 | AA3: =E3/F3*H3 -> 0 | AB3: =(E3/F3)*I3 -> 0 | AC3: =(E3/F3)*J3 -> 1060000 | AD3: =(E3/F3)*K3 -> 990000 | AE3: =(E3/F3)*L3 -> 0 | AF3: =(E3/F3)*M3 -> 0 | AG3: =(E3/F3)*N3 -> 0 | AH3: =(E3/F3)*O3 -> 0 | AI3: =(E3/F3)*P3 -> 0 | AJ3: =(E3/F3)*Q3 -> 162000 | AK3: =(E3/F3)*R3 -> 0 | AL3: =(E3/F3)*S3 -> 0 | AM3: =SUM(AC3:AL3)*0.08 -> 176960 | AN3: =SUM(AC3:AM3) -> 2388960 | AO3: =AN3 -> 2388960 | AP3: =W3 -> TCS | AQ3: AIR | AR3: 50H93043 | AS3: Từ Kho TCS, Hồ Chí Minh đến Bàu Xéo, Hồ Chí Minh | AT3: ADC
A4: PS254506 | B4: 0884325264 | C4: JWE4151001 | D4: 45861 | E4: 155 | F4: 155 | J4: =+IF(F4<=50,1060000, IF(F4<=200, 1210000, IF(F4<=500, 1230000, IF(F4<=1000, 1440000, IF(F4<=2000, 1990000, IF(F4>2000, 1990000+(F4-2000)*1464)))))) -> 1210000 | K4: =990000+70000 -> 1060000 | P4: 731987 | Q4: 220968 | T4: =SUM(J4:S4)*0.08 -> 257836.4 | U4: =SUM(J4:T4) -> 3480791.4 | V4: =U4 -> 3480791.4 | W4: TCS | X4: =A4 -> PS254506 | Y4: =B4 -> 0884325264 | Z4: =D4 -> 45861 | AA4: =E4/F4*H4 -> 0 | AB4: =(E4/F4)*I4 -> 0 | AC4: =(E4/F4)*J4 -> 1210000 | AD4: =(E4/F4)*K4 -> 1060000 | AE4: =(E4/F4)*L4 -> 0 | AF4: =(E4/F4)*M4 -> 0 | AG4: =(E4/F4)*N4 -> 0 | AH4: =(E4/F4)*O4 -> 0 | AI4: =(E4/F4)*P4 -> 731987 | AJ4: =(E4/F4)*Q4 -> 220968 | AK4: =(E4/F4)*R4 -> 0 | AL4: =(E4/F4)*S4 -> 0 | AM4: =SUM(AC4:AL4)*0.08 -> 257836.4 | AN4: =SUM(AC4:AM4) -> 3480791.4 | AO4: =AN4 -> 3480791.4 | AP4: =W4 -> TCS | AQ4: AIR | AR4: 50H93043 | AS4: Từ Kho TCS, Hồ Chí Minh đến Bàu Xéo, Hồ Chí Minh | AT4: ADC
A5: PS254506 | D5: 45861 | F5: 155 | J5: =+IF(F5<=50,1060000, IF(F5<=200, 1210000, IF(F5<=500, 1230000, IF(F5<=1000, 1440000, IF(F5<=2000, 1990000, IF(F5>2000, 1990000+(F5-2000)*1464)))))) -> 1210000 | K5: =990000+70000 -> 1060000 | P5: 731987 | Q5: 220968 | T5: =SUM(J5:S5)*0.08 -> 257836.4 | U5: =SUM(J5:T5) -> 3480791.4 | V5: =U5 -> 3480791.4 | W5: TCS | X5: =A5 -> PS254506 | Y5: =B5 -> 0 | Z5: =D5 -> 45861 | AA5: =E5/F5*H5 -> 0 | AB5: =(E5/F5)*I5 -> 0 | AC5: =(E5/F5)*J5 -> 0 | AD5: =(E5/F5)*K5 -> 0 | AE5: =(E5/F5)*L5 -> 0 | AF5: =(E5/F5)*M5 -> 0 | AG5: =(E5/F5)*N5 -> 0 | AH5: =(E5/F5)*O5 -> 0 | AI5: =(E5/F5)*P5 -> 0 | AJ5: =(E5/F5)*Q5 -> 0 | AK5: =(E5/F5)*R5 -> 0 | AL5: =(E5/F5)*S5 -> 0 | AM5: =SUM(AC5:AL5)*0.08 -> 0 | AN5: =SUM(AC5:AM5) -> 0 | AO5: =AN5 -> 0 | AP5: =W5 -> TCS | AQ5: AIR | AR5: 50H93043 | AS5: Từ Kho TCS, Hồ Chí Minh đến Bàu Xéo, Hồ Chí Minh | AT5: ADC
A6: PS254395 | B6: IE20250710103 | C6: XMNSGN25070195 | D6: 45861 | E6: 87.56 | F6: 87.56 | G6: 0.45 | J6: =+IF(F3=0, _xleta.T, IF(F3<=1000, 1260000, IF(F3<=2000, 1430000, IF(F3<=3000, 2120000, IF(F3<=4500, 2230000, ff))))) -> 1260000 | K6: 990000 | L6: 710910 | O6: 995274 | R6: 1314 | S6: =+IF(F6<=2000, 30000, IF(F6<5000, 66000, ff)) -> 30000 | T6: =SUM(J6:S6)*0.08 -> 318999.84 | U6: =SUM(J6:T6) -> 4306497.8 | V6: =U6 -> 4306497.8 | W6: CÁT LÁI | X6: =A6 -> PS254395 | Y6: =B6 -> IE20250710103 | Z6: =D6 -> 45861 | AA6: =E6/F6*H6 -> 0 | AB6: =(E6/F6)*I6 -> 0 | AC6: =(E6/F6)*J6 -> 1260000 | AD6: =(E6/F6)*K6 -> 990000 | AE6: =(E6/F6)*L6 -> 710910 | AF6: =(E6/F6)*M6 -> 0 | AG6: =(E6/F6)*N6 -> 0 | AH6: =(E6/F6)*O6 -> 995274 | AI6: =(E6/F6)*P6 -> 0 | AJ6: =(E6/F6)*Q6 -> 0 | AK6: =(E6/F6)*R6 -> 1314 | AL6: =(E6/F6)*S6 -> 30000 | AM6: =SUM(AC6:AL6)*0.08 -> 318999.84 | AN6: =SUM(AC6:AM6) -> 4306497.8 | AO6: =AN6 -> 4306497.8 | AP6: =W6 -> CÁT LÁI | AQ6: LCL | AR6: 50H66757 | AS6: Từ Cảng CÁT LÁI đến BÀU XÉO, Đồng Nai | AT6: ADC
A7: PS254381 | B7: T250713Y1 | C7: SPOE2507063 | D7: 45861 | E7: 179.94 | F7: 179.94 | G7: 1.1 | J7: =+IF(F4=0, _xleta.T, IF(F4<=1000, 1260000, IF(F4<=2000, 1430000, IF(F4<=3000, 2120000, IF(F4<=4500, 2230000, ff))))) -> 1260000 | K7: 990000 | L7: 969681 | O7: 1137456 | R7: 2699 | S7: =+IF(F7<=2000, 30000, IF(F7<5000, 66000, ff)) -> 30000 | T7: =SUM(J7:S7)*0.08 -> 351186.88 | U7: =SUM(J7:T7) -> 4741022.9 | V7: =U7 -> 4741022.9 | W7: CÁT LÁI | X7: =A7 -> PS254381 | Y7: =B7 -> T250713Y1 | Z7: =D7 -> 45861 | AA7: =E7/F7*H7 -> 0 | AB7: =(E7/F7)*I7 -> 0 | AC7: =(E7/F7)*J7 -> 1260000 | AD7: =(E7/F7)*K7 -> 990000 | AE7: =(E7/F7)*L7 -> 969681 | AF7: =(E7/F7)*M7 -> 0 | AG7: =(E7/F7)*N7 -> 0 | AH7: =(E7/F7)*O7 -> 1137456 | AI7: =(E7/F7)*P7 -> 0 | AJ7: =(E7/F7)*Q7 -> 0 | AK7: =(E7/F7)*R7 -> 2699 | AL7: =(E7/F7)*S7 -> 30000 | AM7: =SUM(AC7:AL7)*0.08 -> 351186.88 | AN7: =SUM(AC7:AM7) -> 4741022.9 | AO7: =AN7 -> 4741022.9 | AP7: =W7 -> CÁT LÁI | AQ7: LCL | AR7: 50H69181 | AS7: Từ Cảng CÁT LÁI đến BÀU XÉO, Đồng Nai | AT7: ADC
A8: PS254208 | B8: T250710Y1 | C8: SPOE2507049 | D8: 45861 | E8: 220 | F8: 220 | G8: 1.46 | J8: =+IF(F5=0, _xleta.T, IF(F5<=1000, 1260000, IF(F5<=2000, 1430000, IF(F5<=3000, 2120000, IF(F5<=4500, 2230000, ff))))) -> 1260000 | K8: 990000 | L8: 1287520 | O8: 1137888 | R8: 3300 | S8: =+IF(F8<=2000, 30000, IF(F8<5000, 66000, ff)) -> 30000 | T8: =SUM(J8:S8)*0.08 -> 376696.64 | U8: =SUM(J8:T8) -> 5085404.6 | V8: =U8 -> 5085404.6 | W8: CÁT LÁI | X8: =A8 -> PS254208 | Y8: =B8 -> T250710Y1 | Z8: =D8 -> 45861 | AA8: =E8/F8*H8 -> 0 | AB8: =(E8/F8)*I8 -> 0 | AC8: =(E8/F8)*J8 -> 1260000 | AD8: =(E8/F8)*K8 -> 990000 | AE8: =(E8/F8)*L8 -> 1287520 | AF8: =(E8/F8)*M8 -> 0 | AG8: =(E8/F8)*N8 -> 0 | AH8: =(E8/F8)*O8 -> 1137888 | AI8: =(E8/F8)*P8 -> 0 | AJ8: =(E8/F8)*Q8 -> 0 | AK8: =(E8/F8)*R8 -> 3300 | AL8: =(E8/F8)*S8 -> 30000 | AM8: =SUM(AC8:AL8)*0.08 -> 376696.64 | AN8: =SUM(AC8:AM8) -> 5085404.6 | AO8: =AN8 -> 5085404.6 | AP8: =W8 -> CÁT LÁI | AQ8: LCL | AR8: 50H69350 | AS8: Từ Cảng CÁT LÁI đến BÀU XÉO, Đồng Nai | AT8: ADC
A9: PS254496 | B9: INV25070795 | C9: SZVLE2500639 | D9: 45861 | E9: 36 | F9: 36 | G9: 0.12 | J9: =+IF(F6=0, _xleta.T, IF(F6<=1000, 1260000, IF(F6<=2000, 1430000, IF(F6<=3000, 2120000, IF(F6<=4500, 2230000, ff))))) -> 1260000 | K9: 990000 | L9: 512050 | M9: 142236 | N9: 199130 | O9: 853416 | P9: 711180 | R9: 540 | S9: =+IF(F9<=2000, 30000, IF(F9<5000, 66000, ff)) -> 30000 | T9: =SUM(J9:S9)*0.08 -> 375884.16 | U9: =SUM(J9:T9) -> 5074436.2 | V9: =U9 -> 5074436.2 | W9: CÁT LÁI | X9: =A9 -> PS254496 | Y9: =B9 -> INV25070795 | Z9: =D9 -> 45861 | AA9: =E9/F9*H9 -> 0 | AB9: =(E9/F9)*I9 -> 0 | AC9: =(E9/F9)*J9 -> 1260000 | AD9: =(E9/F9)*K9 -> 990000 | AE9: =(E9/F9)*L9 -> 512050 | AF9: =(E9/F9)*M9 -> 142236 | AG9: =(E9/F9)*N9 -> 199130 | AH9: =(E9/F9)*O9 -> 853416 | AI9: =(E9/F9)*P9 -> 711180 | AJ9: =(E9/F9)*Q9 -> 0 | AK9: =(E9/F9)*R9 -> 540 | AL9: =(E9/F9)*S9 -> 30000 | AM9: =SUM(AC9:AL9)*0.08 -> 375884.16 | AN9: =SUM(AC9:AM9) -> 5074436.2 | AO9: =AN9 -> 5074436.2 | AP9: =W9 -> CÁT LÁI | AQ9: LCL | AR9: 50H69181 | AS9: Từ Cảng CÁT LÁI đến BÀU XÉO, Đồng Nai | AT9: ADC
A10: PS254504 | B10: PS254504 | C10: MLHCM2507016 | D10: 45861 | E10: 5298.5 | F10: 5298.5 | G10: 14.402 | J10: =2230000*2 -> 4460000 | K10: 990000 | Q10: 254487 | R10: 79478 | S10: =66000*2 -> 132000 | T10: =SUM(J10:S10)*0.08 -> 473277.2 | U10: =SUM(J10:T10) -> 6389242.2 | V10: =U10 -> 6389242.2 | W10: CÁT LÁI | X10: =A10 -> PS254504 | Y10: =B10 -> PS254504 | Z10: =D10 -> 45861 | AA10: =E10/F10*H10 -> 0 | AB10: =(E10/F10)*I10 -> 0 | AC10: =(E10/F10)*J10 -> 4460000 | AD10: =(E10/F10)*K10 -> 990000 | AE10: =(E10/F10)*L10 -> 0 | AF10: =(E10/F10)*M10 -> 0 | AG10: =(E10/F10)*N10 -> 0 | AH10: =(E10/F10)*O10 -> 0 | AI10: =(E10/F10)*P10 -> 0 | AJ10: =(E10/F10)*Q10 -> 254487 | AK10: =(E10/F10)*R10 -> 79478 | AL10: =(E10/F10)*S10 -> 132000 | AM10: =SUM(AC10:AL10)*0.08 -> 473277.2 | AN10: =SUM(AC10:AM10) -> 6389242.2 | AO10: =AN10 -> 6389242.2 | AP10: =W10 -> CÁT LÁI | AQ10: LCL | AR10: 50H66757 | AS10: Từ Cảng CÁT LÁI đến BÀU XÉO, Đồng Nai | AT10: ADC
A11: PS254491 | B11: 250710JHJ05A | C11: SPOE2507058 | D11: 45861 | E11: 850 | F11: 850 | G11: 1.62 | J11: =+IF(F8=0, _xleta.T, IF(F8<=1000, 1260000, IF(F8<=2000, 1430000, IF(F8<=3000, 2120000, IF(F8<=4500, 2230000, ff))))) -> 1260000 | K11: 990000 | R11: 12750 | S11: =+IF(F11<=2000, 30000, IF(F11<5000, 66000, ff)) -> 30000 | T11: =SUM(J11:S11)*0.08 -> 183420 | U11: =SUM(J11:T11) -> 2476170 | V11: =U11 -> 2476170 | W11: CÁT LÁI | X11: =A11 -> PS254491 | Y11: =B11 -> 250710JHJ05A | Z11: =D11 -> 45861 | AA11: =E11/F11*H11 -> 0 | AB11: =(E11/F11)*I11 -> 0 | AC11: =(E11/F11)*J11 -> 1260000 | AD11: =(E11/F11)*K11 -> 990000 | AE11: =(E11/F11)*L11 -> 0 | AF11: =(E11/F11)*M11 -> 0 | AG11: =(E11/F11)*N11 -> 0 | AH11: =(E11/F11)*O11 -> 0 | AI11: =(E11/F11)*P11 -> 0 | AJ11: =(E11/F11)*Q11 -> 0 | AK11: =(E11/F11)*R11 -> 12750 | AL11: =(E11/F11)*S11 -> 30000 | AM11: =SUM(AC11:AL11)*0.08 -> 183420 | AN11: =SUM(AC11:AM11) -> 2476170 | AO11: =AN11 -> 2476170 | AP11: =W11 -> CÁT LÁI | AQ11: LCL | AR11: 50H69350 | AS11: Từ Cảng CÁT LÁI đến BÀU XÉO, Đồng Nai | AT11: ADC
A12: PS254536 | B12: PC250722VY | C12: JWE4151014 | D12: 45862 | E12: 27 | F12: 27 | J12: =+IF(F12<=50,1060000, IF(F12<=200, 1210000, IF(F12<=500, 1230000, IF(F12<=1000, 1440000, IF(F12<=2000, 1990000, IF(F12>2000, 1990000+(F12-2000)*1464)))))) -> 1060000 | K12: 990000 | P12: 603299 | Q12: 162000 | T12: =SUM(J12:S12)*0.08 -> 225223.92 | U12: =SUM(J12:T12) -> 3040522.9 | V12: =U12 -> 3040522.9 | W12: TCS | X12: =A12 -> PS254536 | Y12: =B12 -> PC250722VY | Z12: =D12 -> 45862 | AA12: =E12/F12*H12 -> 0 | AB12: =(E12/F12)*I12 -> 0 | AC12: =(E12/F12)*J12 -> 1060000 | AD12: =(E12/F12)*K12 -> 990000 | AE12: =(E12/F12)*L12 -> 0 | AF12: =(E12/F12)*M12 -> 0 | AG12: =(E12/F12)*N12 -> 0 | AH12: =(E12/F12)*O12 -> 0 | AI12: =(E12/F12)*P12 -> 603299 | AJ12: =(E12/F12)*Q12 -> 162000 | AK12: =(E12/F12)*R12 -> 0 | AL12: =(E12/F12)*S12 -> 0 | AM12: =SUM(AC12:AL12)*0.08 -> 225223.92 | AN12: =SUM(AC12:AM12) -> 3040522.9 | AO12: =AN12 -> 3040522.9 | AP12: =W12 -> TCS | AQ12: AIR | AR12: 50H69350 | AS12: Từ Kho TCS, Hồ Chí Minh đến Bàu Xéo, Hồ Chí Minh | AT12: ADC
A13: PS254508 | B13: PC250721VY | C13: JWE4151003 | D13: 45862 | E13: 39 | F13: 39 | J13: =+IF(F13<=50,1060000, IF(F13<=200, 1210000, IF(F13<=500, 1230000, IF(F13<=1000, 1440000, IF(F13<=2000, 1990000, IF(F13>2000, 1990000+(F13-2000)*1464)))))) -> 1060000 | K13: 990000 | P13: 624029 | Q13: 162000 | T13: =SUM(J13:S13)*0.08 -> 226882.32 | U13: =SUM(J13:T13) -> 3062911.3 | V13: =U13 -> 3062911.3 | W13: TCS | X13: =A13 -> PS254508 | Y13: =B13 -> PC250721VY | Z13: =D13 -> 45862 | AA13: =E13/F13*H13 -> 0 | AB13: =(E13/F13)*I13 -> 0 | AC13: =(E13/F13)*J13 -> 1060000 | AD13: =(E13/F13)*K13 -> 990000 | AE13: =(E13/F13)*L13 -> 0 | AF13: =(E13/F13)*M13 -> 0 | AG13: =(E13/F13)*N13 -> 0 | AH13: =(E13/F13)*O13 -> 0 | AI13: =(E13/F13)*P13 -> 624029 | AJ13: =(E13/F13)*Q13 -> 162000 | AK13: =(E13/F13)*R13 -> 0 | AL13: =(E13/F13)*S13 -> 0 | AM13: =SUM(AC13:AL13)*0.08 -> 226882.32 | AN13: =SUM(AC13:AM13) -> 3062911.3 | AO13: =AN13 -> 3062911.3 | AP13: =W13 -> TCS | AQ13: AIR | AR13: 50H69350 | AS13: Từ Kho TCS, Hồ Chí Minh đến Bàu Xéo, Hồ Chí Minh | AT13: ADC
A14: PS254507 | B14: G820250721 VY (B) | C14: JWE4150998 | D14: 45862 | E14: 2 | F14: 2 | J14: =+IF(F14<=50,1060000, IF(F14<=200, 1210000, IF(F14<=500, 1230000, IF(F14<=1000, 1440000, IF(F14<=2000, 1990000, IF(F14>2000, 1990000+(F14-2000)*1464)))))) -> 1060000 | K14: 990000 | P14: 564718 | Q14: 162000 | T14: =SUM(J14:S14)*0.08 -> 222137.44 | U14: =SUM(J14:T14) -> 2998855.4 | V14: =U14 -> 2998855.4 | W14: TCS | X14: =A14 -> PS254507 | Y14: =B14 -> G820250721 VY (B) | Z14: =D14 -> 45862 | AA14: =E14/F14*H14 -> 0 | AB14: =(E14/F14)*I14 -> 0 | AC14: =(E14/F14)*J14 -> 1060000 | AD14: =(E14/F14)*K14 -> 990000 | AE14: =(E14/F14)*L14 -> 0 | AF14: =(E14/F14)*M14 -> 0 | AG14: =(E14/F14)*N14 -> 0 | AH14: =(E14/F14)*O14 -> 0 | AI14: =(E14/F14)*P14 -> 564718 | AJ14: =(E14/F14)*Q14 -> 162000 | AK14: =(E14/F14)*R14 -> 0 | AL14: =(E14/F14)*S14 -> 0 | AM14: =SUM(AC14:AL14)*0.08 -> 222137.44 | AN14: =SUM(AC14:AM14) -> 2998855.4 | AO14: =AN14 -> 2998855.4 | AP14: =W14 -> TCS | AQ14: AIR | AR14: 50H69350 | AS14: Từ Kho TCS, Hồ Chí Minh đến Bàu Xéo, Hồ Chí Minh | AT14: ADC
A15: PS254537 | B15: G820250722 VY (B) | C15: JWE4151008 | D15: 45862 | E15: 5 | F15: 5 | J15: =+IF(F15<=50,1060000, IF(F15<=200, 1210000, IF(F15<=500, 1230000, IF(F15<=1000, 1440000, IF(F15<=2000, 1990000, IF(F15>2000, 1990000+(F15-2000)*1464)))))) -> 1060000 | K15: 990000 | P15: 569017 | Q15: 162000 | T15: =SUM(J15:S15)*0.08 -> 222481.36 | U15: =SUM(J15:T15) -> 3003498.4 | V15: =U15 -> 3003498.4 | W15: TCS | X15: =A15 -> PS254537 | Y15: =B15 -> G820250722 VY (B) | Z15: =D15 -> 45862 | AA15: =E15/F15*H15 -> 0 | AB15: =(E15/F15)*I15 -> 0 | AC15: =(E15/F15)*J15 -> 1060000 | AD15: =(E15/F15)*K15 -> 990000 | AE15: =(E15/F15)*L15 -> 0 | AF15: =(E15/F15)*M15 -> 0 | AG15: =(E15/F15)*N15 -> 0 | AH15: =(E15/F15)*O15 -> 0 | AI15: =(E15/F15)*P15 -> 569017 | AJ15: =(E15/F15)*Q15 -> 162000 | AK15: =(E15/F15)*R15 -> 0 | AL15: =(E15/F15)*S15 -> 0 | AM15: =SUM(AC15:AL15)*0.08 -> 222481.36 | AN15: =SUM(AC15:AM15) -> 3003498.4 | AO15: =AN15 -> 3003498.4 | AP15: =W15 -> TCS | AQ15: AIR | AR15: 50H69350 | AS15: Từ Kho TCS, Hồ Chí Minh đến Bàu Xéo, Hồ Chí Minh | AT15: ADC
A16: PS254500 | B16: 0001300107928 | C16: 6518707451 | D16: 45862 | E16: 22 | F16: 22 | K16: 600000 | T16: =SUM(J16:S16)*0.08 -> 48000 | U16: =SUM(J16:T16) -> 648000 | V16: =U16 -> 648000 | W16: DHL | X16: =A16 -> PS254500 | Y16: =B16 -> 0001300107928 | Z16: =D16 -> 45862 | AA16: =E16/F16*H16 -> 0 | AB16: =(E16/F16)*I16 -> 0 | AC16: =(E16/F16)*J16 -> 0 | AD16: =(E16/F16)*K16 -> 600000 | AE16: =(E16/F16)*L16 -> 0 | AF16: =(E16/F16)*M16 -> 0 | AG16: =(E16/F16)*N16 -> 0 | AH16: =(E16/F16)*O16 -> 0 | AI16: =(E16/F16)*P16 -> 0 | AJ16: =(E16/F16)*Q16 -> 0 | AK16: =(E16/F16)*R16 -> 0 | AL16: =(E16/F16)*S16 -> 0 | AM16: =SUM(AC16:AL16)*0.08 -> 48000 | AN16: =SUM(AC16:AM16) -> 648000 | AO16: =AN16 -> 648000 | AP16: =W16 -> DHL | AQ16: EXP
A17: PS254448 | B17: OHTY250894 | C17: 7671539315 | D17: 45862 | E17: 4.9 | F17: 4.9 | K17: 600000 | T17: =SUM(J17:S17)*0.08 -> 48000 | U17: =SUM(J17:T17) -> 648000 | V17: =U17 -> 648000 | W17: DHL | X17: =A17 -> PS254448 | Y17: =B17 -> OHTY250894 | Z17: =D17 -> 45862 | AA17: =E17/F17*H17 -> 0 | AB17: =(E17/F17)*I17 -> 0 | AC17: =(E17/F17)*J17 -> 0 | AD17: =(E17/F17)*K17 -> 600000 | AE17: =(E17/F17)*L17 -> 0 | AF17: =(E17/F17)*M17 -> 0 | AG17: =(E17/F17)*N17 -> 0 | AH17: =(E17/F17)*O17 -> 0 | AI17: =(E17/F17)*P17 -> 0 | AJ17: =(E17/F17)*Q17 -> 0 | AK17: =(E17/F17)*R17 -> 0 | AL17: =(E17/F17)*S17 -> 0 | AM17: =SUM(AC17:AL17)*0.08 -> 48000 | AN17: =SUM(AC17:AM17) -> 648000 | AO17: =AN17 -> 648000 | AP17: =W17 -> DHL | AQ17: EXP
A18: PS254449 | B18: ZSSCIPSO2507003 | C18: 7671846114 | D18: 45862 | E18: 8.5 | F18: 8.5 | K18: 600000 | T18: =SUM(J18:S18)*0.08 -> 48000 | U18: =SUM(J18:T18) -> 648000 | V18: =U18 -> 648000 | W18: DHL | X18: =A18 -> PS254449 | Y18: =B18 -> ZSSCIPSO2507003 | Z18: =D18 -> 45862 | AA18: =E18/F18*H18 -> 0 | AB18: =(E18/F18)*I18 -> 0 | AC18: =(E18/F18)*J18 -> 0 | AD18: =(E18/F18)*K18 -> 600000 | AE18: =(E18/F18)*L18 -> 0 | AF18: =(E18/F18)*M18 -> 0 | AG18: =(E18/F18)*N18 -> 0 | AH18: =(E18/F18)*O18 -> 0 | AI18: =(E18/F18)*P18 -> 0 | AJ18: =(E18/F18)*Q18 -> 0 | AK18: =(E18/F18)*R18 -> 0 | AL18: =(E18/F18)*S18 -> 0 | AM18: =SUM(AC18:AL18)*0.08 -> 48000 | AN18: =SUM(AC18:AM18) -> 648000 | AO18: =AN18 -> 648000 | AP18: =W18 -> DHL | AQ18: EXP
A19: PS254505 | B19: INV25070863 | C19: 7671273341 | D19: 45862 | E19: 6 | F19: 6 | K19: 600000 | T19: =SUM(J19:S19)*0.08 -> 48000 | U19: =SUM(J19:T19) -> 648000 | V19: =U19 -> 648000 | W19: DHL | X19: =A19 -> PS254505 | Y19: =B19 -> INV25070863 | Z19: =D19 -> 45862 | AA19: =E19/F19*H19 -> 0 | AB19: =(E19/F19)*I19 -> 0 | AC19: =(E19/F19)*J19 -> 0 | AD19: =(E19/F19)*K19 -> 600000 | AE19: =(E19/F19)*L19 -> 0 | AF19: =(E19/F19)*M19 -> 0 | AG19: =(E19/F19)*N19 -> 0 | AH19: =(E19/F19)*O19 -> 0 | AI19: =(E19/F19)*P19 -> 0 | AJ19: =(E19/F19)*Q19 -> 0 | AK19: =(E19/F19)*R19 -> 0 | AL19: =(E19/F19)*S19 -> 0 | AM19: =SUM(AC19:AL19)*0.08 -> 48000 | AN19: =SUM(AC19:AM19) -> 648000 | AO19: =AN19 -> 648000 | AP19: =W19 -> DHL | AQ19: EXP
A20: PS254503 | B20: DJL250718027 | C20: 7671997583 | D20: 45862 | E20: 16.7 | F20: 16.7 | J20: =+IF(F20<=50,1060000, IF(F20<=200, 1210000, IF(F20<=500, 1230000, IF(F20<=1000, 1440000, IF(F20<=2000, 1990000, IF(F20>2000, 1990000+(F20-2000)*1464)))))) -> 1060000 | K20: =600000+70000 -> 670000 | T20: =SUM(J20:S20)*0.08 -> 138400 | U20: =SUM(J20:T20) -> 1868400 | V20: =U20 -> 1868400 | W20: DHL | X20: =A20 -> PS254503 | Y20: =B20 -> DJL250718027 | Z20: =D20 -> 45862 | AA20: =E20/F20*H20 -> 0 | AB20: =(E20/F20)*I20 -> 0 | AC20: =(E20/F20)*J20 -> 1060000 | AD20: =(E20/F20)*K20 -> 670000 | AE20: =(E20/F20)*L20 -> 0 | AF20: =(E20/F20)*M20 -> 0 | AG20: =(E20/F20)*N20 -> 0 | AH20: =(E20/F20)*O20 -> 0 | AI20: =(E20/F20)*P20 -> 0 | AJ20: =(E20/F20)*Q20 -> 0 | AK20: =(E20/F20)*R20 -> 0 | AL20: =(E20/F20)*S20 -> 0 | AM20: =SUM(AC20:AL20)*0.08 -> 138400 | AN20: =SUM(AC20:AM20) -> 1868400 | AO20: =AN20 -> 1868400 | AP20: =W20 -> DHL | AQ20: EXP
A21: PS254503 | D21: 45862 | F21: 16.7 | J21: =+IF(F21<=50,1060000, IF(F21<=200, 1210000, IF(F21<=500, 1230000, IF(F21<=1000, 1440000, IF(F21<=2000, 1990000, IF(F21>2000, 1990000+(F21-2000)*1464)))))) -> 1060000 | K21: =600000+70000 -> 670000 | T21: =SUM(J21:S21)*0.08 -> 138400 | U21: =SUM(J21:T21) -> 1868400 | V21: =U21 -> 1868400 | W21: DHL | X21: =A21 -> PS254503 | Y21: =B21 -> 0 | Z21: =D21 -> 45862 | AA21: =E21/F21*H21 -> 0 | AB21: =(E21/F21)*I21 -> 0 | AC21: =(E21/F21)*J21 -> 0 | AD21: =(E21/F21)*K21 -> 0 | AE21: =(E21/F21)*L21 -> 0 | AF21: =(E21/F21)*M21 -> 0 | AG21: =(E21/F21)*N21 -> 0 | AH21: =(E21/F21)*O21 -> 0 | AI21: =(E21/F21)*P21 -> 0 | AJ21: =(E21/F21)*Q21 -> 0 | AK21: =(E21/F21)*R21 -> 0 | AL21: =(E21/F21)*S21 -> 0 | AM21: =SUM(AC21:AL21)*0.08 -> 0 | AN21: =SUM(AC21:AM21) -> 0 | AO21: =AN21 -> 0 | AP21: =W21 -> DHL | AQ21: EXP
A22: PS254527 | B22: EX25070108 | C22: 6037520510 | D22: 45862 | E22: 4.1 | F22: 4.1 | K22: 600000 | T22: =SUM(J22:S22)*0.08 -> 48000 | U22: =SUM(J22:T22) -> 648000 | V22: =U22 -> 648000 | W22: DHL | X22: =A22 -> PS254527 | Y22: =B22 -> EX25070108 | Z22: =D22 -> 45862 | AA22: =E22/F22*H22 -> 0 | AB22: =(E22/F22)*I22 -> 0 | AC22: =(E22/F22)*J22 -> 0 | AD22: =(E22/F22)*K22 -> 600000 | AE22: =(E22/F22)*L22 -> 0 | AF22: =(E22/F22)*M22 -> 0 | AG22: =(E22/F22)*N22 -> 0 | AH22: =(E22/F22)*O22 -> 0 | AI22: =(E22/F22)*P22 -> 0 | AJ22: =(E22/F22)*Q22 -> 0 | AK22: =(E22/F22)*R22 -> 0 | AL22: =(E22/F22)*S22 -> 0 | AM22: =SUM(AC22:AL22)*0.08 -> 48000 | AN22: =SUM(AC22:AM22) -> 648000 | AO22: =AN22 -> 648000 | AP22: =W22 -> DHL | AQ22: EXP
A23: PS254526 | B23: HF250719 | C23: 7672071606 | D23: 45862 | E23: 19.2 | F23: 19.2 | J23: =+IF(F23<=50,1060000, IF(F23<=200, 1210000, IF(F23<=500, 1230000, IF(F23<=1000, 1440000, IF(F23<=2000, 1990000, IF(F23>2000, 1990000+(F23-2000)*1464)))))) -> 1060000 | K23: =600000+70000 -> 670000 | T23: =SUM(J23:S23)*0.08 -> 138400 | U23: =SUM(J23:T23) -> 1868400 | V23: =U23 -> 1868400 | W23: DHL | X23: =A23 -> PS254526 | Y23: =B23 -> HF250719 | Z23: =D23 -> 45862 | AA23: =E23/F23*H23 -> 0 | AB23: =(E23/F23)*I23 -> 0 | AC23: =(E23/F23)*J23 -> 1060000 | AD23: =(E23/F23)*K23 -> 670000 | AE23: =(E23/F23)*L23 -> 0 | AF23: =(E23/F23)*M23 -> 0 | AG23: =(E23/F23)*N23 -> 0 | AH23: =(E23/F23)*O23 -> 0 | AI23: =(E23/F23)*P23 -> 0 | AJ23: =(E23/F23)*Q23 -> 0 | AK23: =(E23/F23)*R23 -> 0 | AL23: =(E23/F23)*S23 -> 0 | AM23: =SUM(AC23:AL23)*0.08 -> 138400 | AN23: =SUM(AC23:AM23) -> 1868400 | AO23: =AN23 -> 1868400 | AP23: =W23 -> DHL | AQ23: EXP
A24: PS254526 | D24: 45862 | F24: 19.2 | J24: =+IF(F24<=50,1060000, IF(F24<=200, 1210000, IF(F24<=500, 1230000, IF(F24<=1000, 1440000, IF(F24<=2000, 1990000, IF(F24>2000, 1990000+(F24-2000)*1464)))))) -> 1060000 | K24: =600000+70000 -> 670000 | T24: =SUM(J24:S24)*0.08 -> 138400 | U24: =SUM(J24:T24) -> 1868400 | V24: =U24 -> 1868400 | W24: DHL | X24: =A24 -> PS254526 | Y24: =B24 -> 0 | Z24: =D24 -> 45862 | AA24: =E24/F24*H24 -> 0 | AB24: =(E24/F24)*I24 -> 0 | AC24: =(E24/F24)*J24 -> 0 | AD24: =(E24/F24)*K24 -> 0 | AE24: =(E24/F24)*L24 -> 0 | AF24: =(E24/F24)*M24 -> 0 | AG24: =(E24/F24)*N24 -> 0 | AH24: =(E24/F24)*O24 -> 0 | AI24: =(E24/F24)*P24 -> 0 | AJ24: =(E24/F24)*Q24 -> 0 | AK24: =(E24/F24)*R24 -> 0 | AL24: =(E24/F24)*S24 -> 0 | AM24: =SUM(AC24:AL24)*0.08 -> 0 | AN24: =SUM(AC24:AM24) -> 0 | AO24: =AN24 -> 0 | AP24: =W24 -> DHL | AQ24: EXP
A25: PS254543 | B25: SO42008 | C25: 7672182372 | D25: 45862 | E25: 9.3 | F25: 9.3 | K25: 600000 | T25: =SUM(J25:S25)*0.08 -> 48000 | U25: =SUM(J25:T25) -> 648000 | V25: =U25 -> 648000 | W25: DHL | X25: =A25 -> PS254543 | Y25: =B25 -> SO42008 | Z25: =D25 -> 45862 | AA25: =E25/F25*H25 -> 0 | AB25: =(E25/F25)*I25 -> 0 | AC25: =(E25/F25)*J25 -> 0 | AD25: =(E25/F25)*K25 -> 600000 | AE25: =(E25/F25)*L25 -> 0 | AF25: =(E25/F25)*M25 -> 0 | AG25: =(E25/F25)*N25 -> 0 | AH25: =(E25/F25)*O25 -> 0 | AI25: =(E25/F25)*P25 -> 0 | AJ25: =(E25/F25)*Q25 -> 0 | AK25: =(E25/F25)*R25 -> 0 | AL25: =(E25/F25)*S25 -> 0 | AM25: =SUM(AC25:AL25)*0.08 -> 48000 | AN25: =SUM(AC25:AM25) -> 648000 | AO25: =AN25 -> 648000 | AP25: =W25 -> DHL | AQ25: EXP
A26: PS254545 | B26: 4794463 | C26: 6674889852 | D26: 45862 | E26: 55 | F26: 55 | K26: 600000 | T26: =SUM(J26:S26)*0.08 -> 48000 | U26: =SUM(J26:T26) -> 648000 | V26: =U26 -> 648000 | W26: DHL | X26: =A26 -> PS254545 | Y26: =B26 -> 4794463 | Z26: =D26 -> 45862 | AA26: =E26/F26*H26 -> 0 | AB26: =(E26/F26)*I26 -> 0 | AC26: =(E26/F26)*J26 -> 0 | AD26: =(E26/F26)*K26 -> 600000 | AE26: =(E26/F26)*L26 -> 0 | AF26: =(E26/F26)*M26 -> 0 | AG26: =(E26/F26)*N26 -> 0 | AH26: =(E26/F26)*O26 -> 0 | AI26: =(E26/F26)*P26 -> 0 | AJ26: =(E26/F26)*Q26 -> 0 | AK26: =(E26/F26)*R26 -> 0 | AL26: =(E26/F26)*S26 -> 0 | AM26: =SUM(AC26:AL26)*0.08 -> 48000 | AN26: =SUM(AC26:AM26) -> 648000 | AO26: =AN26 -> 648000 | AP26: =W26 -> DHL | AQ26: EXP
A27: PS254493 | B27: INJF250709 | C27: DGPE25070055 | D27: 45862 | E27: 1410 | F27: 1410 | G27: 4.76 | J27: =+IF(F24=0, _xleta.T, IF(F24<=1000, 1260000, IF(F24<=2000, 1430000, IF(F24<=3000, 2120000, IF(F24<=4500, 2230000, ff))))) -> 1260000 | K27: 990000 | L27: 17596444 | M27: 3383931.6 | N27: 5414291.6 | O27: 1421820 | R27: 21150 | S27: =+IF(F27<=2000, 30000, IF(F27<5000, 66000, ff)) -> 30000 | T27: =SUM(J27:S27)*0.08 -> 2409411 | U27: =SUM(J27:T27) -> 32527048 | V27: =U27 -> 32527048 | W27: CÁT LÁI | X27: =A27 -> PS254493 | Y27: =B27 -> INJF250709 | Z27: =D27 -> 45862 | AA27: =E27/F27*H27 -> 0 | AB27: =(E27/F27)*I27 -> 0 | AC27: =(E27/F27)*J27 -> 1260000 | AD27: =(E27/F27)*K27 -> 990000 | AE27: =(E27/F27)*L27 -> 17596444 | AF27: =(E27/F27)*M27 -> 3383931.6 | AG27: =(E27/F27)*N27 -> 5414291.6 | AH27: =(E27/F27)*O27 -> 1421820 | AI27: =(E27/F27)*P27 -> 0 | AJ27: =(E27/F27)*Q27 -> 0 | AK27: =(E27/F27)*R27 -> 21150 | AL27: =(E27/F27)*S27 -> 30000 | AM27: =SUM(AC27:AL27)*0.08 -> 2409411 | AN27: =SUM(AC27:AM27) -> 32527048 | AO27: =AN27 -> 32527048 | AP27: =W27 -> CÁT LÁI | AQ27: LCL | AR27: 50H93234 | AS27: Từ Cảng CÁT LÁI đến BÀU XÉO, Đồng Nai | AT27: ADC
A28: PS254492 | B28: 4780698 | C28: 112500034967156 | D28: 45862 | E28: 521.96 | F28: 521.96 | K28: 410000 | T28: =SUM(J28:S28)*0.08 -> 32800 | U28: =SUM(J28:T28) -> 442800 | V28: =U28 -> 442800 | W28: KNQ TBS | X28: =A28 -> PS254492 | Y28: =B28 -> 4780698 | Z28: =D28 -> 45862 | AA28: =E28/F28*H28 -> 0 | AB28: =(E28/F28)*I28 -> 0 | AC28: =(E28/F28)*J28 -> 0 | AD28: =(E28/F28)*K28 -> 410000 | AE28: =(E28/F28)*L28 -> 0 | AF28: =(E28/F28)*M28 -> 0 | AG28: =(E28/F28)*N28 -> 0 | AH28: =(E28/F28)*O28 -> 0 | AI28: =(E28/F28)*P28 -> 0 | AJ28: =(E28/F28)*Q28 -> 0 | AK28: =(E28/F28)*R28 -> 0 | AL28: =(E28/F28)*S28 -> 0 | AM28: =SUM(AC28:AL28)*0.08 -> 32800 | AN28: =SUM(AC28:AM28) -> 442800 | AO28: =AN28 -> 442800 | AP28: =W28 -> KNQ TBS | AQ28: LCL-KNQ
A29: PS254540 | B29: A25060676 | C29: 112500035315500 | D29: 45862 | E29: 4957.72 | F29: 4957.72 | K29: 410000 | T29: =SUM(J29:S29)*0.08 -> 32800 | U29: =SUM(J29:T29) -> 442800 | V29: =U29 -> 442800 | W29: KNQ CANG DN | X29: =A29 -> PS254540 | Y29: =B29 -> A25060676 | Z29: =D29 -> 45862 | AA29: =E29/F29*H29 -> 0 | AB29: =(E29/F29)*I29 -> 0 | AC29: =(E29/F29)*J29 -> 0 | AD29: =(E29/F29)*K29 -> 410000 | AE29: =(E29/F29)*L29 -> 0 | AF29: =(E29/F29)*M29 -> 0 | AG29: =(E29/F29)*N29 -> 0 | AH29: =(E29/F29)*O29 -> 0 | AI29: =(E29/F29)*P29 -> 0 | AJ29: =(E29/F29)*Q29 -> 0 | AK29: =(E29/F29)*R29 -> 0 | AL29: =(E29/F29)*S29 -> 0 | AM29: =SUM(AC29:AL29)*0.08 -> 32800 | AN29: =SUM(AC29:AM29) -> 442800 | AO29: =AN29 -> 442800 | AP29: =W29 -> KNQ CANG DN | AQ29: LCL-KNQ
A30: PS254566 | B30: 0884335886 | C30: JWE4151018 | D30: 45863 | E30: 76 | F30: 76 | J30: =+IF(F30<=50,1060000, IF(F30<=200, 1210000, IF(F30<=500, 1230000, IF(F30<=1000, 1440000, IF(F30<=2000, 1990000, IF(F30>2000, 1990000+(F30-2000)*1464)))))) -> 1210000 | K30: =990000+70000 -> 1060000 | P30: 617284 | Q30: 162000 | T30: =SUM(J30:S30)*0.08 -> 243942.72 | U30: =SUM(J30:T30) -> 3293226.7 | V30: =U30 -> 3293226.7 | W30: TCS | X30: =A30 -> PS254566 | Y30: =B30 -> 0884335886 | Z30: =D30 -> 45863 | AA30: =E30/F30*H30 -> 0 | AB30: =(E30/F30)*I30 -> 0 | AC30: =(E30/F30)*J30 -> 1210000 | AD30: =(E30/F30)*K30 -> 1060000 | AE30: =(E30/F30)*L30 -> 0 | AF30: =(E30/F30)*M30 -> 0 | AG30: =(E30/F30)*N30 -> 0 | AH30: =(E30/F30)*O30 -> 0 | AI30: =(E30/F30)*P30 -> 617284 | AJ30: =(E30/F30)*Q30 -> 162000 | AK30: =(E30/F30)*R30 -> 0 | AL30: =(E30/F30)*S30 -> 0 | AM30: =SUM(AC30:AL30)*0.08 -> 243942.72 | AN30: =SUM(AC30:AM30) -> 3293226.7 | AO30: =AN30 -> 3293226.7 | AP30: =W30 -> TCS | AQ30: AIR | AR30: 50H93043 | AS30: Từ Kho TCS, Hồ Chí Minh đến Bàu Xéo, Hồ Chí Minh | AT30: ADC
A31: PS254566 | D31: 45863 | F31: 76 | J31: =+IF(F31<=50,1060000, IF(F31<=200, 1210000, IF(F31<=500, 1230000, IF(F31<=1000, 1440000, IF(F31<=2000, 1990000, IF(F31>2000, 1990000+(F31-2000)*1464)))))) -> 1210000 | K31: =990000+70000 -> 1060000 | P31: 617284 | Q31: 162000 | T31: =SUM(J31:S31)*0.08 -> 243942.72 | U31: =SUM(J31:T31) -> 3293226.7 | V31: =U31 -> 3293226.7 | W31: TCS | X31: =A31 -> PS254566 | Y31: =B31 -> 0 | Z31: =D31 -> 45863 | AA31: =E31/F31*H31 -> 0 | AB31: =(E31/F31)*I31 -> 0 | AC31: =(E31/F31)*J31 -> 0 | AD31: =(E31/F31)*K31 -> 0 | AE31: =(E31/F31)*L31 -> 0 | AF31: =(E31/F31)*M31 -> 0 | AG31: =(E31/F31)*N31 -> 0 | AH31: =(E31/F31)*O31 -> 0 | AI31: =(E31/F31)*P31 -> 0 | AJ31: =(E31/F31)*Q31 -> 0 | AK31: =(E31/F31)*R31 -> 0 | AL31: =(E31/F31)*S31 -> 0 | AM31: =SUM(AC31:AL31)*0.08 -> 0 | AN31: =SUM(AC31:AM31) -> 0 | AO31: =AN31 -> 0 | AP31: =W31 -> TCS | AQ31: AIR | AR31: 50H93043 | AS31: Từ Kho TCS, Hồ Chí Minh đến Bàu Xéo, Hồ Chí Minh | AT31: ADC
A32: PS254565 | B32: PC250723VY | C32: JWE4151020 | D32: 45863 | E32: 6 | F32: 6 | J32: =+IF(F32<=50,1060000, IF(F32<=200, 1210000, IF(F32<=500, 1230000, IF(F32<=1000, 1440000, IF(F32<=2000, 1990000, IF(F32>2000, 1990000+(F32-2000)*1464)))))) -> 1060000 | K32: 990000 | P32: 570467 | Q32: 162000 | T32: =SUM(J32:S32)*0.08 -> 222597.36 | U32: =SUM(J32:T32) -> 3005064.4 | V32: =U32 -> 3005064.4 | W32: TCS | X32: =A32 -> PS254565 | Y32: =B32 -> PC250723VY | Z32: =D32 -> 45863 | AA32: =E32/F32*H32 -> 0 | AB32: =(E32/F32)*I32 -> 0 | AC32: =(E32/F32)*J32 -> 1060000 | AD32: =(E32/F32)*K32 -> 990000 | AE32: =(E32/F32)*L32 -> 0 | AF32: =(E32/F32)*M32 -> 0 | AG32: =(E32/F32)*N32 -> 0 | AH32: =(E32/F32)*O32 -> 0 | AI32: =(E32/F32)*P32 -> 570467 | AJ32: =(E32/F32)*Q32 -> 162000 | AK32: =(E32/F32)*R32 -> 0 | AL32: =(E32/F32)*S32 -> 0 | AM32: =SUM(AC32:AL32)*0.08 -> 222597.36 | AN32: =SUM(AC32:AM32) -> 3005064.4 | AO32: =AN32 -> 3005064.4 | AP32: =W32 -> TCS | AQ32: AIR | AR32: 50H93043 | AS32: Từ Kho TCS, Hồ Chí Minh đến Bàu Xéo, Hồ Chí Minh | AT32: ADC
A33: PS254564 | B33: G820250723 VY (B) | C33: JWE4151017 | D33: 45863 | E33: 3 | F33: 3 | J33: =+IF(F33<=50,1060000, IF(F33<=200, 1210000, IF(F33<=500, 1230000, IF(F33<=1000, 1440000, IF(F33<=2000, 1990000, IF(F33>2000, 1990000+(F33-2000)*1464)))))) -> 1060000 | K33: 990000 | P33: 566118 | Q33: 162000 | T33: =SUM(J33:S33)*0.08 -> 222249.44 | U33: =SUM(J33:T33) -> 3000367.4 | V33: =U33 -> 3000367.4 | W33: TCS | X33: =A33 -> PS254564 | Y33: =B33 -> G820250723 VY (B) | Z33: =D33 -> 45863 | AA33: =E33/F33*H33 -> 0 | AB33: =(E33/F33)*I33 -> 0 | AC33: =(E33/F33)*J33 -> 1060000 | AD33: =(E33/F33)*K33 -> 990000 | AE33: =(E33/F33)*L33 -> 0 | AF33: =(E33/F33)*M33 -> 0 | AG33: =(E33/F33)*N33 -> 0 | AH33: =(E33/F33)*O33 -> 0 | AI33: =(E33/F33)*P33 -> 566118 | AJ33: =(E33/F33)*Q33 -> 162000 | AK33: =(E33/F33)*R33 -> 0 | AL33: =(E33/F33)*S33 -> 0 | AM33: =SUM(AC33:AL33)*0.08 -> 222249.44 | AN33: =SUM(AC33:AM33) -> 3000367.4 | AO33: =AN33 -> 3000367.4 | AP33: =W33 -> TCS | AQ33: AIR | AR33: 50H93043 | AS33: Từ Kho TCS, Hồ Chí Minh đến Bàu Xéo, Hồ Chí Minh | AT33: ADC
A34: PS254520 | B34: D214530 | C34: GXSAG25070765 | D34: 45863 | E34: 1558 | F34: 1558 | G34: 6.1 | J34: =+IF(F31=0, _xleta.T, IF(F31<=1000, 1260000, IF(F31<=2000, 1430000, IF(F31<=3000, 2120000, IF(F31<=4500, 2230000, ff))))) -> 1260000 | K34: 990000 | L34: 1767559.4 | M34: 1767560.4 | N34: 1414048.3 | O34: 724410 | P34: 579528 | R34: 23370 | S34: =+IF(F34<=2000, 30000, IF(F34<5000, 66000, ff)) -> 30000 | T34: =SUM(J34:S34)*0.08 -> 684518.09 | U34: =SUM(J34:T34) -> 9240994.2 | V34: =U34 -> 9240994.2 | W34: CÁT LÁI | X34: =A34 -> PS254520 | Y34: =B34 -> D214530 | Z34: =D34 -> 45863 | AA34: =E34/F34*H34 -> 0 | AB34: =(E34/F34)*I34 -> 0 | AC34: =(E34/F34)*J34 -> 1260000 | AD34: =(E34/F34)*K34 -> 990000 | AE34: =(E34/F34)*L34 -> 1767559.4 | AF34: =(E34/F34)*M34 -> 1767560.4 | AG34: =(E34/F34)*N34 -> 1414048.3 | AH34: =(E34/F34)*O34 -> 724410 | AI34: =(E34/F34)*P34 -> 579528 | AJ34: =(E34/F34)*Q34 -> 0 | AK34: =(E34/F34)*R34 -> 23370 | AL34: =(E34/F34)*S34 -> 30000 | AM34: =SUM(AC34:AL34)*0.08 -> 684518.09 | AN34: =SUM(AC34:AM34) -> 9240994.2 | AO34: =AN34 -> 9240994.2 | AP34: =W34 -> CÁT LÁI | AQ34: LCL | AR34: 50H66757 | AS34: Từ Cảng CÁT LÁI đến BÀU XÉO, Đồng Nai | AT34: ADC
A35: PS254598 | B35: T250723Y2 | C35: SPX2507028 | D35: 45864 | E35: 41 | F35: 41 | J35: =+IF(F35<=50,1060000, IF(F35<=200, 1210000, IF(F35<=500, 1230000, IF(F35<=1000, 1440000, IF(F35<=2000, 1990000, IF(F35>2000, 1990000+(F35-2000)*1464)))))) -> 1060000 | K35: 990000 | Q35: 162000 | T35: =SUM(J35:S35)*0.08 -> 176960 | U35: =SUM(J35:T35) -> 2388960 | V35: =U35 -> 2388960 | W35: TCS | X35: =A35 -> PS254598 | Y35: =B35 -> T250723Y2 | Z35: =D35 -> 45864 | AA35: =E35/F35*H35 -> 0 | AB35: =(E35/F35)*I35 -> 0 | AC35: =(E35/F35)*J35 -> 1060000 | AD35: =(E35/F35)*K35 -> 990000 | AE35: =(E35/F35)*L35 -> 0 | AF35: =(E35/F35)*M35 -> 0 | AG35: =(E35/F35)*N35 -> 0 | AH35: =(E35/F35)*O35 -> 0 | AI35: =(E35/F35)*P35 -> 0 | AJ35: =(E35/F35)*Q35 -> 162000 | AK35: =(E35/F35)*R35 -> 0 | AL35: =(E35/F35)*S35 -> 0 | AM35: =SUM(AC35:AL35)*0.08 -> 176960 | AN35: =SUM(AC35:AM35) -> 2388960 | AO35: =AN35 -> 2388960 | AP35: =W35 -> TCS | AQ35: AIR | AR35: 50H69350 | AS35: Từ Kho TCS, Hồ Chí Minh đến Bàu Xéo, Hồ Chí Minh | AT35: ADC
A36: PS254591 | B36: PC250724VY | C36: JWE4151027 | D36: 45864 | E36: 22 | F36: 22 | J36: =+IF(F36<=50,1060000, IF(F36<=200, 1210000, IF(F36<=500, 1230000, IF(F36<=1000, 1440000, IF(F36<=2000, 1990000, IF(F36>2000, 1990000+(F36-2000)*1464)))))) -> 1060000 | K36: 990000 | P36: 592497 | Q36: 162000 | T36: =SUM(J36:S36)*0.08 -> 224359.76 | U36: =SUM(J36:T36) -> 3028856.8 | V36: =U36 -> 3028856.8 | W36: TCS | X36: =A36 -> PS254591 | Y36: =B36 -> PC250724VY | Z36: =D36 -> 45864 | AA36: =E36/F36*H36 -> 0 | AB36: =(E36/F36)*I36 -> 0 | AC36: =(E36/F36)*J36 -> 1060000 | AD36: =(E36/F36)*K36 -> 990000 | AE36: =(E36/F36)*L36 -> 0 | AF36: =(E36/F36)*M36 -> 0 | AG36: =(E36/F36)*N36 -> 0 | AH36: =(E36/F36)*O36 -> 0 | AI36: =(E36/F36)*P36 -> 592497 | AJ36: =(E36/F36)*Q36 -> 162000 | AK36: =(E36/F36)*R36 -> 0 | AL36: =(E36/F36)*S36 -> 0 | AM36: =SUM(AC36:AL36)*0.08 -> 224359.76 | AN36: =SUM(AC36:AM36) -> 3028856.8 | AO36: =AN36 -> 3028856.8 | AP36: =W36 -> TCS | AQ36: AIR | AR36: 50H69350 | AS36: Từ Kho TCS, Hồ Chí Minh đến Bàu Xéo, Hồ Chí Minh | AT36: ADC
A37: PS254592 | B37: G820250724VY (B) | C37: JWE4151029 | D37: 45864 | E37: 4 | F37: 4 | J37: =+IF(F37<=50,1060000, IF(F37<=200, 1210000, IF(F37<=500, 1230000, IF(F37<=1000, 1440000, IF(F37<=2000, 1990000, IF(F37>2000, 1990000+(F37-2000)*1464)))))) -> 1060000 | K37: 990000 | P37: 567170 | Q37: 162000 | T37: =SUM(J37:S37)*0.08 -> 222333.6 | U37: =SUM(J37:T37) -> 3001503.6 | V37: =U37 -> 3001503.6 | W37: TCS | X37: =A37 -> PS254592 | Y37: =B37 -> G820250724VY (B) | Z37: =D37 -> 45864 | AA37: =E37/F37*H37 -> 0 | AB37: =(E37/F37)*I37 -> 0 | AC37: =(E37/F37)*J37 -> 1060000 | AD37: =(E37/F37)*K37 -> 990000 | AE37: =(E37/F37)*L37 -> 0 | AF37: =(E37/F37)*M37 -> 0 | AG37: =(E37/F37)*N37 -> 0 | AH37: =(E37/F37)*O37 -> 0 | AI37: =(E37/F37)*P37 -> 567170 | AJ37: =(E37/F37)*Q37 -> 162000 | AK37: =(E37/F37)*R37 -> 0 | AL37: =(E37/F37)*S37 -> 0 | AM37: =SUM(AC37:AL37)*0.08 -> 222333.6 | AN37: =SUM(AC37:AM37) -> 3001503.6 | AO37: =AN37 -> 3001503.6 | AP37: =W37 -> TCS | AQ37: AIR | AR37: 50H69350 | AS37: Từ Kho TCS, Hồ Chí Minh đến Bàu Xéo, Hồ Chí Minh | AT37: ADC
A38: PS254544 | B38: DJL250721028 | C38: 7672150485 | E38: 0.2 | F38: 0.2 | K38: 600000 | T38: =SUM(J38:S38)*0.08 -> 48000 | U38: =SUM(J38:T38) -> 648000 | V38: =U38 -> 648000 | W38: DHL | X38: =A38 -> PS254544 | Y38: =B38 -> DJL250721028 | Z38: =D38 -> 0 | AA38: =E38/F38*H38 -> 0 | AB38: =(E38/F38)*I38 -> 0 | AC38: =(E38/F38)*J38 -> 0 | AD38: =(E38/F38)*K38 -> 600000 | AE38: =(E38/F38)*L38 -> 0 | AF38: =(E38/F38)*M38 -> 0 | AG38: =(E38/F38)*N38 -> 0 | AH38: =(E38/F38)*O38 -> 0 | AI38: =(E38/F38)*P38 -> 0 | AJ38: =(E38/F38)*Q38 -> 0 | AK38: =(E38/F38)*R38 -> 0 | AL38: =(E38/F38)*S38 -> 0 | AM38: =SUM(AC38:AL38)*0.08 -> 48000 | AN38: =SUM(AC38:AM38) -> 648000 | AO38: =AN38 -> 648000 | AP38: =W38 -> DHL | AQ38: EXP
A39: PS254556 | B39: 1045/2025 | C39: 5597048995 | E39: 27 | F39: 27 | K39: 600000 | T39: =SUM(J39:S39)*0.08 -> 48000 | U39: =SUM(J39:T39) -> 648000 | V39: =U39 -> 648000 | W39: DHL | X39: =A39 -> PS254556 | Y39: =B39 -> 1045/2025 | Z39: =D39 -> 0 | AA39: =E39/F39*H39 -> 0 | AB39: =(E39/F39)*I39 -> 0 | AC39: =(E39/F39)*J39 -> 0 | AD39: =(E39/F39)*K39 -> 600000 | AE39: =(E39/F39)*L39 -> 0 | AF39: =(E39/F39)*M39 -> 0 | AG39: =(E39/F39)*N39 -> 0 | AH39: =(E39/F39)*O39 -> 0 | AI39: =(E39/F39)*P39 -> 0 | AJ39: =(E39/F39)*Q39 -> 0 | AK39: =(E39/F39)*R39 -> 0 | AL39: =(E39/F39)*S39 -> 0 | AM39: =SUM(AC39:AL39)*0.08 -> 48000 | AN39: =SUM(AC39:AM39) -> 648000 | AO39: =AN39 -> 648000 | AP39: =W39 -> DHL | AQ39: EXP
A40: PS254569 | B40: INV25071002 | C40: 610971955290 | E40: 339.8 | F40: 339.8 | K40: 600000 | T40: =SUM(J40:S40)*0.08 -> 48000 | U40: =SUM(J40:T40) -> 648000 | V40: =U40 -> 648000 | W40: FEDEX | X40: =A40 -> PS254569 | Y40: =B40 -> INV25071002 | Z40: =D40 -> 0 | AA40: =E40/F40*H40 -> 0 | AB40: =(E40/F40)*I40 -> 0 | AC40: =(E40/F40)*J40 -> 0 | AD40: =(E40/F40)*K40 -> 600000 | AE40: =(E40/F40)*L40 -> 0 | AF40: =(E40/F40)*M40 -> 0 | AG40: =(E40/F40)*N40 -> 0 | AH40: =(E40/F40)*O40 -> 0 | AI40: =(E40/F40)*P40 -> 0 | AJ40: =(E40/F40)*Q40 -> 0 | AK40: =(E40/F40)*R40 -> 0 | AL40: =(E40/F40)*S40 -> 0 | AM40: =SUM(AC40:AL40)*0.08 -> 48000 | AN40: =SUM(AC40:AM40) -> 648000 | AO40: =AN40 -> 648000 | AP40: =W40 -> FEDEX | AQ40: EXP
...

Sheet LCL+LOCAL - IMPORT   (2)
A1: LCL + LOCAL
A2: No | B2: INVOICE No | C2: AWB,B/L No | D2: DATE C/D | E2: Declaration | F2: Number of CD | G2: KGS | H2: KGS OF BL | I2: CBM | J2: FREIGHT AIR | K2: FREIGHT SEA | L2: TRUCKING FEE | M2: SERVICE FEE | N2: CFS | O2: CIC | P2: THC | Q2: D/O | R2: HANDLING | S2: STORAGE | T2: CSHT | U2: TOLL FEE | V2: INCURRED | W2: VAT PASS THROUGH | X2: CLEARING EXPENSE | Y2: TOTAL | Z2: SỐ XE | AA2: PORT | AB2: No | AC2: INVOICE No | AD2: DATE | AE2: FREIGHT AIR PER P/L | AF2: FREIGHT SEA PER P/L | AG2: TRUCKING FEE | AH2: SERVICE FEE | AI2: CFS | AJ2: CIC | AK2: THC | AL2: D/O | AM2: HANDLING | AN2: STORAGE | AO2: CSHT | AP2: TOLL FEE | AQ2: INCURRED | AR2: VAT PASS THROUGH | AS2: CLEARING EXPENSE PER P/L | AT2: TOTAL | AU2: PORT | AW2: SỐ JOB FILE OF ADC | AX2: Nơi đi - Nơi đến | AY2: NGÀY GIAO HÀNG
A3: PS260717 | B3: EX-26010076 | C3: SE26010032/003 | D3: 46051 | E3: 107938104260 | F3: 1 | G3: 194.46 | H3: 194.46 | I3: 0.832 | L3: {=IF(H3=0, _xleta.T, IF(H3<=1000, 1290000, IF(H3<=2000, 1460000, IF(H3<=3000, 2186000, IF(H3<=5000, 2296000, ff)))))} -> 1290000 | M3: 940500 | Z3: 50H-69181 | AA3: CÁT LÁI | AB3: =A3 -> PS260717 | AC3: =B3 -> EX-26010076 | AD3: =D3 -> 46051 | AE3: =G3/H3*J3 -> 0 | AF3: =(G3/H3)*K3 -> 0 | AG3: =(G3/H3)*L3 -> 1290000 | AH3: =(G3/H3)*M3 -> 940500 | AI3: =(G3/H3)*N3 -> 0 | AJ3: =(G3/H3)*O3 -> 0 | AK3: =(G3/H3)*P3 -> 0 | AL3: =(G3/H3)*Q3 -> 0 | AM3: =(G3/H3)*R3 -> 0 | AN3: =(G3/H3)*S3 -> 0 | AO3: =(G3/H3)*T3 -> 0 | AP3: =(G3/H3)*U3 -> 0 | AQ3: =(G3/H3)*V3 -> 0 | AR3: =SUM(AG3:AQ3)*0.08 -> 178440 | AS3: =SUM(AG3:AR3) -> 2408940 | AT3: =AS3 -> 2408940 | AU3: =AA3 -> CÁT LÁI | AV3: LCL | AW3: ADCDNB-26.01-004426 | AX3: , từ Cảng Cát Lái đến KCN Bàu Xéo, Đồng Nai | AY3: 46055 | AZ3: 50H-69181 50H-66757 | BA3: 2 X 5MT
A4: PS260508 | B4: OHTY260012 | C4: 08SEA2601035 | D4: 46052 | E4: 107942880510 | F4: 1 | G4: 666 | H4: 666 | I4: 5.032 | L4: {=IF(H4=0, _xleta.T, IF(H4<=1000, 1290000, IF(H4<=2000, 1460000, IF(H4<=3000, 2186000, IF(H4<=5000, 2296000, ff)))))} -> 1290000 | M4: 940500 | AA4: CÁT LÁI | AB4: =A4 -> PS260508 | AC4: =B4 -> OHTY260012 | AD4: =D4 -> 46052 | AE4: =G4/H4*J4 -> 0 | AF4: =(G4/H4)*K4 -> 0 | AG4: =(G4/H4)*L4 -> 1290000 | AH4: =(G4/H4)*M4 -> 940500 | AI4: =(G4/H4)*N4 -> 0 | AJ4: =(G4/H4)*O4 -> 0 | AK4: =(G4/H4)*P4 -> 0 | AL4: =(G4/H4)*Q4 -> 0 | AM4: =(G4/H4)*R4 -> 0 | AN4: =(G4/H4)*S4 -> 0 | AO4: =(G4/H4)*T4 -> 0 | AP4: =(G4/H4)*U4 -> 0 | AQ4: =(G4/H4)*V4 -> 0 | AR4: =SUM(AG4:AQ4)*0.08 -> 178440 | AS4: =SUM(AG4:AR4) -> 2408940 | AT4: =AS4 -> 2408940 | AU4: =AA4 -> CÁT LÁI | AV4: LCL | AW4: ADCDNB-26.01-004616 | AX4: , từ Cảng Cát Lái đến KCN Bàu Xéo, Đồng Nai | AY4: 46055
A5: PS260746 | B5: 5204969 | C5: S02096936 | D5: 46051 | E5: 107940077120 | F5: 1 | G5: 241.98 | H5: 241.98 | I5: 1.474 | L5: {=IF(H5=0, _xleta.T, IF(H5<=1000, 1290000, IF(H5<=2000, 1460000, IF(H5<=3000, 2186000, IF(H5<=5000, 2296000, ff)))))} -> 1290000 | M5: 940500 | Z5: 50H-66757 | AA5: CÁT LÁI | AB5: =A5 -> PS260746 | AC5: =B5 -> 5204969 | AD5: =D5 -> 46051 | AE5: =G5/H5*J5 -> 0 | AF5: =(G5/H5)*K5 -> 0 | AG5: =(G5/H5)*L5 -> 1290000 | AH5: =(G5/H5)*M5 -> 940500 | AI5: =(G5/H5)*N5 -> 0 | AJ5: =(G5/H5)*O5 -> 0 | AK5: =(G5/H5)*P5 -> 0 | AL5: =(G5/H5)*Q5 -> 0 | AM5: =(G5/H5)*R5 -> 0 | AN5: =(G5/H5)*S5 -> 0 | AO5: =(G5/H5)*T5 -> 0 | AP5: =(G5/H5)*U5 -> 0 | AQ5: =(G5/H5)*V5 -> 0 | AR5: =SUM(AG5:AQ5)*0.08 -> 178440 | AS5: =SUM(AG5:AR5) -> 2408940 | AT5: =AS5 -> 2408940 | AU5: =AA5 -> CÁT LÁI | AV5: LCL | AW5: ADCDNB-26.01-004617 | AX5: , từ Cảng Cát Lái đến KCN Bàu Xéo, Đồng Nai | AY5: 46055
A6: PS260737 | B6: 5196209 | C6: CGH/HCM-018/26 | D6: 46052 | E6: 107943625640 | F6: 1 | G6: 191.6 | H6: 191.6 | I6: 0.86 | L6: {=IF(H6=0, _xleta.T, IF(H6<=1000, 1290000, IF(H6<=2000, 1460000, IF(H6<=3000, 2186000, IF(H6<=5000, 2296000, ff)))))} -> 1290000 | M6: 940500 | AA6: CÁT LÁI | AB6: =A6 -> PS260737 | AC6: =B6 -> 5196209 | AD6: =D6 -> 46052 | AE6: =G6/H6*J6 -> 0 | AF6: =(G6/H6)*K6 -> 0 | AG6: =(G6/H6)*L6 -> 1290000 | AH6: =(G6/H6)*M6 -> 940500 | AI6: =(G6/H6)*N6 -> 0 | AJ6: =(G6/H6)*O6 -> 0 | AK6: =(G6/H6)*P6 -> 0 | AL6: =(G6/H6)*Q6 -> 0 | AM6: =(G6/H6)*R6 -> 0 | AN6: =(G6/H6)*S6 -> 0 | AO6: =(G6/H6)*T6 -> 0 | AP6: =(G6/H6)*U6 -> 0 | AQ6: =(G6/H6)*V6 -> 0 | AR6: =SUM(AG6:AQ6)*0.08 -> 178440 | AS6: =SUM(AG6:AR6) -> 2408940 | AT6: =AS6 -> 2408940 | AU6: =AA6 -> CÁT LÁI | AV6: LCL | AW6: ADCDNB-26.01-004619 | AX6: , từ Cảng Cát Lái đến KCN Bàu Xéo, Đồng Nai | AY6: 46055
A7: PS260716 | B7: PS26-716 | C7: CGH/HCM-018/26A | D7: 46052 | E7: 107943647930 | F7: 1 | G7: 792.5 | H7: 792.5 | I7: 1.91 | L7: {=IF(H7=0, _xleta.T, IF(H7<=1000, 1290000, IF(H7<=2000, 1460000, IF(H7<=3000, 2186000, IF(H7<=5000, 2296000, ff)))))} -> 1290000 | M7: 940500 | Z7: 50H-69181 | AA7: CÁT LÁI | AB7: =A7 -> PS260716 | AC7: =B7 -> PS26-716 | AD7: =D7 -> 46052 | AE7: =G7/H7*J7 -> 0 | AF7: =(G7/H7)*K7 -> 0 | AG7: =(G7/H7)*L7 -> 1290000 | AH7: =(G7/H7)*M7 -> 940500 | AI7: =(G7/H7)*N7 -> 0 | AJ7: =(G7/H7)*O7 -> 0 | AK7: =(G7/H7)*P7 -> 0 | AL7: =(G7/H7)*Q7 -> 0 | AM7: =(G7/H7)*R7 -> 0 | AN7: =(G7/H7)*S7 -> 0 | AO7: =(G7/H7)*T7 -> 0 | AP7: =(G7/H7)*U7 -> 0 | AQ7: =(G7/H7)*V7 -> 0 | AR7: =SUM(AG7:AQ7)*0.08 -> 178440 | AS7: =SUM(AG7:AR7) -> 2408940 | AT7: =AS7 -> 2408940 | AU7: =AA7 -> CÁT LÁI | AV7: LCL | AW7: ADCDNB-26.01-004636 | AX7: , từ Cảng Cát Lái đến KCN Bàu Xéo, Đồng Nai | AY7: 46055
A8: PS260742 | B8: PS26-742 | C8: CGH/HCM-018/26B | D8: 46052 | E8: 107943576750 | F8: 1 | G8: 2511 | H8: 2511 | I8: 6.38 | L8: {=IF(H8=0, _xleta.T, IF(H8<=1000, 1290000, IF(H8<=2000, 1460000, IF(H8<=3000, 2186000, IF(H8<=5000, 2296000, ff)))))} -> 2186000 | M8: 940500 | Z8: 50H-66757 | AA8: CÁT LÁI | AB8: =A8 -> PS260742 | AC8: =B8 -> PS26-742 | AD8: =D8 -> 46052 | AE8: =G8/H8*J8 -> 0 | AF8: =(G8/H8)*K8 -> 0 | AG8: =(G8/H8)*L8 -> 2186000 | AH8: =(G8/H8)*M8 -> 940500 | AI8: =(G8/H8)*N8 -> 0 | AJ8: =(G8/H8)*O8 -> 0 | AK8: =(G8/H8)*P8 -> 0 | AL8: =(G8/H8)*Q8 -> 0 | AM8: =(G8/H8)*R8 -> 0 | AN8: =(G8/H8)*S8 -> 0 | AO8: =(G8/H8)*T8 -> 0 | AP8: =(G8/H8)*U8 -> 0 | AQ8: =(G8/H8)*V8 -> 0 | AR8: =SUM(AG8:AQ8)*0.08 -> 250120 | AS8: =SUM(AG8:AR8) -> 3376620 | AT8: =AS8 -> 3376620 | AU8: =AA8 -> CÁT LÁI | AV8: LCL | AW8: ADCDNB-26.01-004637 | AX8: , từ Cảng Cát Lái đến KCN Bàu Xéo, Đồng Nai | AY8: 46055
A9: PS260768 | B9: 2603/SLTW-PS | C9: 112600036770481 | D9: 46052 | E9: 107944314110 | F9: 1 | G9: 7867 | H9: 7867 | L9: =2596000*2 -> 5192000 | M9: 940500 | Z9: 50E46443 60H11265 | AA9: TAN THUAN | AB9: =A9 -> PS260768 | AC9: =B9 -> 2603/SLTW-PS | AD9: =D9 -> 46052 | AE9: =G9/H9*J9 -> 0 | AF9: =(G9/H9)*K9 -> 0 | AG9: =(G9/H9)*L9 -> 5192000 | AH9: =(G9/H9)*M9 -> 940500 | AI9: =(G9/H9)*N9 -> 0 | AJ9: =(G9/H9)*O9 -> 0 | AK9: =(G9/H9)*P9 -> 0 | AL9: =(G9/H9)*Q9 -> 0 | AM9: =(G9/H9)*R9 -> 0 | AN9: =(G9/H9)*S9 -> 0 | AO9: =(G9/H9)*T9 -> 0 | AP9: =(G9/H9)*U9 -> 0 | AQ9: =(G9/H9)*V9 -> 0 | AR9: =SUM(AG9:AQ9)*0.08 -> 490600 | AS9: =SUM(AG9:AR9) -> 6623100 | AT9: =AS9 -> 6623100 | AU9: =AA9 -> TAN THUAN | AV9: LCL | AW9: ADCDNB-26.01-004627 | AX9: , từ Tân Thuận về KCN Bàu Xéo, Đồng Nai | AY9: 46055 | AZ9: 50E46443 60H11265 | BA9: 2 X 5MT
A10: PS260788 | B10: PC260130VY | C10: JWE5150187 | D10: 46055 | E10: 107946861300 | F10: 1 | G10: 17 | H10: 17 | L10: =IF(H10<=50,1060000, IF(H10<=200, 1210000, IF(H10<=500, 1230000, IF(H10<=1000, 1440000, IF(H10<=2000, 1990000, IF(H10>2000, 1990000+(H10-2000)*1464)))))) -> 1060000 | M10: 940500 | Z10: 50H69104 | AA10: TCS | AB10: =A10 -> PS260788 | AC10: =B10 -> PC260130VY | AD10: =D10 -> 46055 | AE10: =G10/H10*J10 -> 0 | AF10: =(G10/H10)*K10 -> 0 | AG10: =(G10/H10)*L10 -> 1060000 | AH10: =(G10/H10)*M10 -> 940500 | AI10: =(G10/H10)*N10 -> 0 | AJ10: =(G10/H10)*O10 -> 0 | AK10: =(G10/H10)*P10 -> 0 | AL10: =(G10/H10)*Q10 -> 0 | AM10: =(G10/H10)*R10 -> 0 | AN10: =(G10/H10)*S10 -> 0 | AO10: =(G10/H10)*T10 -> 0 | AP10: =(G10/H10)*U10 -> 0 | AQ10: =(G10/H10)*V10 -> 0 | AR10: =SUM(AG10:AQ10)*0.08 -> 160040 | AS10: =SUM(AG10:AR10) -> 2160540 | AT10: =AS10 -> 2160540 | AU10: =AA10 -> TCS | AV10: AIR | AW10: ADCDNB-26.01-004700 | AX10: , từ Kho TCS đến KCN Bàu Xéo , Đồng Nai | AY10: 46056 | AZ10: 50H69104 | BA10: 1 X 1MT
A11: PS260775 | B11: HH20260128001 | C11: 8704238410 | D11: 46052 | E11: 107944026410 | F11: 1 | G11: 5.7 | H11: 5.7 | M11: 570000 | AA11: DHL | AB11: =A11 -> PS260775 | AC11: =B11 -> HH20260128001 | AD11: =D11 -> 46052 | AE11: =G11/H11*J11 -> 0 | AF11: =(G11/H11)*K11 -> 0 | AG11: =(G11/H11)*L11 -> 0 | AH11: =(G11/H11)*M11 -> 570000 | AI11: =(G11/H11)*N11 -> 0 | AJ11: =(G11/H11)*O11 -> 0 | AK11: =(G11/H11)*P11 -> 0 | AL11: =(G11/H11)*Q11 -> 0 | AM11: =(G11/H11)*R11 -> 0 | AN11: =(G11/H11)*S11 -> 0 | AO11: =(G11/H11)*T11 -> 0 | AP11: =(G11/H11)*U11 -> 0 | AQ11: =(G11/H11)*V11 -> 0 | AR11: =SUM(AG11:AQ11)*0.08 -> 45600 | AS11: =SUM(AG11:AR11) -> 615600 | AT11: =AS11 -> 615600 | AU11: =AA11 -> DHL | AV11: EXP | AW11: ADCDNB-26.01-004630
A12: PS260772 | B12: EXD1-26-VY0127 | C12: 8704018536 | D12: 46053 | E12: 107946396610 | F12: 1 | G12: 19.5 | H12: 19.5 | M12: 570000 | AA12: DHL | AB12: =A12 -> PS260772 | AC12: =B12 -> EXD1-26-VY0127 | AD12: =D12 -> 46053 | AE12: =G12/H12*J12 -> 0 | AF12: =(G12/H12)*K12 -> 0 | AG12: =(G12/H12)*L12 -> 0 | AH12: =(G12/H12)*M12 -> 570000 | AI12: =(G12/H12)*N12 -> 0 | AJ12: =(G12/H12)*O12 -> 0 | AK12: =(G12/H12)*P12 -> 0 | AL12: =(G12/H12)*Q12 -> 0 | AM12: =(G12/H12)*R12 -> 0 | AN12: =(G12/H12)*S12 -> 0 | AO12: =(G12/H12)*T12 -> 0 | AP12: =(G12/H12)*U12 -> 0 | AQ12: =(G12/H12)*V12 -> 0 | AR12: =SUM(AG12:AQ12)*0.08 -> 45600 | AS12: =SUM(AG12:AR12) -> 615600 | AT12: =AS12 -> 615600 | AU12: =AA12 -> DHL | AV12: EXP | AW12: ADCDNB-26.02-000302
A13: PS260777 | B13: AT26010642 | C13: 2819783746 | D13: 46053 | E13: 107946398450 | F13: 1 | G13: 16 | H13: 16 | M13: 570000 | AA13: DHL | AB13: =A13 -> PS260777 | AC13: =B13 -> AT26010642 | AD13: =D13 -> 46053 | AE13: =G13/H13*J13 -> 0 | AF13: =(G13/H13)*K13 -> 0 | AG13: =(G13/H13)*L13 -> 0 | AH13: =(G13/H13)*M13 -> 570000 | AI13: =(G13/H13)*N13 -> 0 | AJ13: =(G13/H13)*O13 -> 0 | AK13: =(G13/H13)*P13 -> 0 | AL13: =(G13/H13)*Q13 -> 0 | AM13: =(G13/H13)*R13 -> 0 | AN13: =(G13/H13)*S13 -> 0 | AO13: =(G13/H13)*T13 -> 0 | AP13: =(G13/H13)*U13 -> 0 | AQ13: =(G13/H13)*V13 -> 0 | AR13: =SUM(AG13:AQ13)*0.08 -> 45600 | AS13: =SUM(AG13:AR13) -> 615600 | AT13: =AS13 -> 615600 | AU13: =AA13 -> DHL | AV13: EXP | AW13: ADCDNB-26.02-000303
A14: PS260771 | B14: 005/IEM/I/26 | C14: 4471973100 | D14: 46053 | E14: 107946400110 | F14: 1 | G14: 10.2 | H14: 10.2 | M14: 570000 | AA14: DHL | AB14: =A14 -> PS260771 | AC14: =B14 -> 005/IEM/I/26 | AD14: =D14 -> 46053 | AE14: =G14/H14*J14 -> 0 | AF14: =(G14/H14)*K14 -> 0 | AG14: =(G14/H14)*L14 -> 0 | AH14: =(G14/H14)*M14 -> 570000 | AI14: =(G14/H14)*N14 -> 0 | AJ14: =(G14/H14)*O14 -> 0 | AK14: =(G14/H14)*P14 -> 0 | AL14: =(G14/H14)*Q14 -> 0 | AM14: =(G14/H14)*R14 -> 0 | AN14: =(G14/H14)*S14 -> 0 | AO14: =(G14/H14)*T14 -> 0 | AP14: =(G14/H14)*U14 -> 0 | AQ14: =(G14/H14)*V14 -> 0 | AR14: =SUM(AG14:AQ14)*0.08 -> 45600 | AS14: =SUM(AG14:AR14) -> 615600 | AT14: =AS14 -> 615600 | AU14: =AA14 -> DHL | AV14: EXP | AW14: ADCDNB-26.02-000304
A15: PS260760 | B15: T260122-Y1 | C15: SPOE2601123 | D15: 46052 | E15: 107940953260 | F15: 1 | G15: 668.89 | H15: 668.89 | I15: 2.732 | L15: {=IF(H15=0, _xleta.T, IF(H15<=1000, 1290000, IF(H15<=2000, 1460000, IF(H15<=3000, 2186000, IF(H15<=5000, 2296000, ff)))))} -> 1290000 | M15: 940500 | Z15: 50E46291 | AA15: CÁT LÁI | AB15: =A15 -> PS260760 | AC15: =B15 -> T260122-Y1 | AD15: =D15 -> 46052 | AE15: =G15/H15*J15 -> 0 | AF15: =(G15/H15)*K15 -> 0 | AG15: =(G15/H15)*L15 -> 1290000 | AH15: =(G15/H15)*M15 -> 940500 | AI15: =(G15/H15)*N15 -> 0 | AJ15: =(G15/H15)*O15 -> 0 | AK15: =(G15/H15)*P15 -> 0 | AL15: =(G15/H15)*Q15 -> 0 | AM15: =(G15/H15)*R15 -> 0 | AN15: =(G15/H15)*S15 -> 0 | AO15: =(G15/H15)*T15 -> 0 | AP15: =(G15/H15)*U15 -> 0 | AQ15: =(G15/H15)*V15 -> 0 | AR15: =SUM(AG15:AQ15)*0.08 -> 178440 | AS15: =SUM(AG15:AR15) -> 2408940 | AT15: =AS15 -> 2408940 | AU15: =AA15 -> CÁT LÁI | AV15: LCL | AW15: ADCDNB-26.01-004618 | AX15: , từ Cảng Cát Lái đến KCN Bàu Xéo, Đồng Nai | AY15: 46056 | AZ15: 50E46291 | BA15: 1 X 2MT
A16: PS260748 | B16: EXD1-26-C037 | C16: HTHC26012481 | D16: 46053 | E16: 107946468930 | F16: 1 | G16: 502 | H16: 502 | I16: 1 | L16: {=IF(H16=0, _xleta.T, IF(H16<=1000, 1290000, IF(H16<=2000, 1460000, IF(H16<=3000, 2186000, IF(H16<=5000, 2296000, ff)))))} -> 1290000 | M16: 940500 | Z16: 50E46291 | AA16: CÁT LÁI | AB16: =A16 -> PS260748 | AC16: =B16 -> EXD1-26-C037 | AD16: =D16 -> 46053 | AE16: =G16/H16*J16 -> 0 | AF16: =(G16/H16)*K16 -> 0 | AG16: =(G16/H16)*L16 -> 1290000 | AH16: =(G16/H16)*M16 -> 940500 | AI16: =(G16/H16)*N16 -> 0 | AJ16: =(G16/H16)*O16 -> 0 | AK16: =(G16/H16)*P16 -> 0 | AL16: =(G16/H16)*Q16 -> 0 | AM16: =(G16/H16)*R16 -> 0 | AN16: =(G16/H16)*S16 -> 0 | AO16: =(G16/H16)*T16 -> 0 | AP16: =(G16/H16)*U16 -> 0 | AQ16: =(G16/H16)*V16 -> 0 | AR16: =SUM(AG16:AQ16)*0.08 -> 178440 | AS16: =SUM(AG16:AR16) -> 2408940 | AT16: =AS16 -> 2408940 | AU16: =AA16 -> CÁT LÁI | AV16: LCL | AW16: ADCDNB-26.02-000305 | AX16: , từ Cảng Cát Lái đến KCN Bàu Xéo, Đồng Nai | AY16: 46056
A17: PS260774 | B17: 260121-02 | C17: 20SEA26010169 | D17: 46053 | E17: 107946490300 | F17: 1 | G17: 573 | H17: 573 | I17: 0.9 | L17: {=IF(H17=0, _xleta.T, IF(H17<=1000, 1290000, IF(H17<=2000, 1460000, IF(H17<=3000, 2186000, IF(H17<=5000, 2296000, ff)))))} -> 1290000 | M17: 940500 | Z17: 50E46291 | AA17: CÁT LÁI | AB17: =A17 -> PS260774 | AC17: =B17 -> 260121-02 | AD17: =D17 -> 46053 | AE17: =G17/H17*J17 -> 0 | AF17: =(G17/H17)*K17 -> 0 | AG17: =(G17/H17)*L17 -> 1290000 | AH17: =(G17/H17)*M17 -> 940500 | AI17: =(G17/H17)*N17 -> 0 | AJ17: =(G17/H17)*O17 -> 0 | AK17: =(G17/H17)*P17 -> 0 | AL17: =(G17/H17)*Q17 -> 0 | AM17: =(G17/H17)*R17 -> 0 | AN17: =(G17/H17)*S17 -> 0 | AO17: =(G17/H17)*T17 -> 0 | AP17: =(G17/H17)*U17 -> 0 | AQ17: =(G17/H17)*V17 -> 0 | AR17: =SUM(AG17:AQ17)*0.08 -> 178440 | AS17: =SUM(AG17:AR17) -> 2408940 | AT17: =AS17 -> 2408940 | AU17: =AA17 -> CÁT LÁI | AV17: LCL | AW17: ADCDNB-26.02-000306 | AX17: , từ Cảng Cát Lái đến KCN Bàu Xéo, Đồng Nai | AY17: 46056
A18: PS260837 | B18: 0885089482 | C18: JWE5150192 | D18: 46056 | E18: 107953699600 | F18: 2 | G18: 2.2 | H18: =G18+G19 -> 237 | L18: =IF(H18<=50,1060000, IF(H18<=200, 1210000, IF(H18<=500, 1230000, IF(H18<=1000, 1440000, IF(H18<=2000, 1990000, IF(H18>2000, 1990000+(H18-2000)*1464)))))) -> 1230000 | M18: =940500+70000 -> 1010500 | Z18: 50H70505 | AA18: TCS | AB18: =A18 -> PS260837 | AC18: =B18 -> 0885089482 | AD18: =D18 -> 46056 | AE18: =G18/H18*J18 -> 0 | AF18: =(G18/H18)*K18 -> 0 | AG18: =(G18/H18)*L18 -> 11417.722 | AH18: =(G18/H18)*M18 -> 9380.1688 | AI18: =(G18/H18)*N18 -> 0 | AJ18: =(G18/H18)*O18 -> 0 | AK18: =(G18/H18)*P18 -> 0 | AL18: =(G18/H18)*Q18 -> 0 | AM18: =(G18/H18)*R18 -> 0 | AN18: =(G18/H18)*S18 -> 0 | AO18: =(G18/H18)*T18 -> 0 | AP18: =(G18/H18)*U18 -> 0 | AQ18: =(G18/H18)*V18 -> 0 | AR18: =SUM(AG18:AQ18)*0.08 -> 1663.8312 | AS18: =SUM(AG18:AR18) -> 22461.722 | AT18: =AS18 -> 22461.722 | AU18: =AA18 -> TCS | AV18: AIR | AW18: ADCDNB-26.02-000382 | AX18: , từ Kho TCS đến KCN Bàu Xéo , Đồng Nai | AY18: 46057 | AZ18: 50H70505 | BA18: 1 X 1MT
A19: PS260837 | B19: 0885090860 | C19: JWE5150192 | D19: 46056 | E19: 107953739830 | G19: 234.8 | H19: 237 | L19: =IF(H19<=50,1060000, IF(H19<=200, 1210000, IF(H19<=500, 1230000, IF(H19<=1000, 1440000, IF(H19<=2000, 1990000, IF(H19>2000, 1990000+(H19-2000)*1464)))))) -> 1230000 | M19: =940500+70000 -> 1010500 | Z19: 50H70505 | AA19: TCS | AB19: =A19 -> PS260837 | AC19: =B19 -> 0885090860 | AD19: =D19 -> 46056 | AE19: =G19/H19*J19 -> 0 | AF19: =(G19/H19)*K19 -> 0 | AG19: =(G19/H19)*L19 -> 1218582.3 | AH19: =(G19/H19)*M19 -> 1001119.8 | AI19: =(G19/H19)*N19 -> 0 | AJ19: =(G19/H19)*O19 -> 0 | AK19: =(G19/H19)*P19 -> 0 | AL19: =(G19/H19)*Q19 -> 0 | AM19: =(G19/H19)*R19 -> 0 | AN19: =(G19/H19)*S19 -> 0 | AO19: =(G19/H19)*T19 -> 0 | AP19: =(G19/H19)*U19 -> 0 | AQ19: =(G19/H19)*V19 -> 0 | AR19: =SUM(AG19:AQ19)*0.08 -> 177576.17 | AS19: =SUM(AG19:AR19) -> 2397278.3 | AT19: =AS19 -> 2397278.3 | AU19: =AA19 -> TCS | AV19: AIR | AW19: ADCDNB-26.02-000382 | AX19: , từ Kho TCS đến KCN Bàu Xéo , Đồng Nai | AY19: 46057
A20: PS260835 | B20: PC260202VY | C20: JWE5150195 | D20: 46056 | E20: 107953153600 | F20: 1 | G20: 32 | H20: 32 | L20: =IF(H20<=50,1060000, IF(H20<=200, 1210000, IF(H20<=500, 1230000, IF(H20<=1000, 1440000, IF(H20<=2000, 1990000, IF(H20>2000, 1990000+(H20-2000)*1464)))))) -> 1060000 | M20: 940500 | Z20: 50H70505 | AA20: TCS | AB20: =A20 -> PS260835 | AC20: =B20 -> PC260202VY | AD20: =D20 -> 46056 | AE20: =G20/H20*J20 -> 0 | AF20: =(G20/H20)*K20 -> 0 | AG20: =(G20/H20)*L20 -> 1060000 | AH20: =(G20/H20)*M20 -> 940500 | AI20: =(G20/H20)*N20 -> 0 | AJ20: =(G20/H20)*O20 -> 0 | AK20: =(G20/H20)*P20 -> 0 | AL20: =(G20/H20)*Q20 -> 0 | AM20: =(G20/H20)*R20 -> 0 | AN20: =(G20/H20)*S20 -> 0 | AO20: =(G20/H20)*T20 -> 0 | AP20: =(G20/H20)*U20 -> 0 | AQ20: =(G20/H20)*V20 -> 0 | AR20: =SUM(AG20:AQ20)*0.08 -> 160040 | AS20: =SUM(AG20:AR20) -> 2160540 | AT20: =AS20 -> 2160540 | AU20: =AA20 -> TCS | AV20: AIR | AW20: ADCDNB-26.02-000381 | AX20: , từ Kho TCS đến KCN Bàu Xéo , Đồng Nai | AY20: 46057
A21: PS260806 | B21: LW260129 | C21: 5397965591 | D21: 46056 | E21: 107952134730 | F21: 1 | G21: 32.5 | H21: 32.5 | M21: 570000 | AA21: DHL | AB21: =A21 -> PS260806 | AC21: =B21 -> LW260129 | AD21: =D21 -> 46056 | AE21: =G21/H21*J21 -> 0 | AF21: =(G21/H21)*K21 -> 0 | AG21: =(G21/H21)*L21 -> 0 | AH21: =(G21/H21)*M21 -> 570000 | AI21: =(G21/H21)*N21 -> 0 | AJ21: =(G21/H21)*O21 -> 0 | AK21: =(G21/H21)*P21 -> 0 | AL21: =(G21/H21)*Q21 -> 0 | AM21: =(G21/H21)*R21 -> 0 | AN21: =(G21/H21)*S21 -> 0 | AO21: =(G21/H21)*T21 -> 0 | AP21: =(G21/H21)*U21 -> 0 | AQ21: =(G21/H21)*V21 -> 0 | AR21: =SUM(AG21:AQ21)*0.08 -> 45600 | AS21: =SUM(AG21:AR21) -> 615600 | AT21: =AS21 -> 615600 | AU21: =AA21 -> DHL | AV21: EXP | AW21: ADCDNB-26.02-000449
A22: PS260812 | B22: DJL-260130-007 | C22: 5162691741 | D22: 46055 | E22: 107951879560 | F22: 1 | G22: 0.9 | H22: 0.9 | M22: 570000 | AA22: DHL | AB22: =A22 -> PS260812 | AC22: =B22 -> DJL-260130-007 | AD22: =D22 -> 46055 | AE22: =G22/H22*J22 -> 0 | AF22: =(G22/H22)*K22 -> 0 | AG22: =(G22/H22)*L22 -> 0 | AH22: =(G22/H22)*M22 -> 570000 | AI22: =(G22/H22)*N22 -> 0 | AJ22: =(G22/H22)*O22 -> 0 | AK22: =(G22/H22)*P22 -> 0 | AL22: =(G22/H22)*Q22 -> 0 | AM22: =(G22/H22)*R22 -> 0 | AN22: =(G22/H22)*S22 -> 0 | AO22: =(G22/H22)*T22 -> 0 | AP22: =(G22/H22)*U22 -> 0 | AQ22: =(G22/H22)*V22 -> 0 | AR22: =SUM(AG22:AQ22)*0.08 -> 45600 | AS22: =SUM(AG22:AR22) -> 615600 | AT22: =AS22 -> 615600 | AU22: =AA22 -> DHL | AV22: EXP | AW22: ADCDNB-26.02-000450
A23: PS260814 | B23: IV260103194 | C23: 5162712752 | D23: 46055 | E23: 107951921560 | F23: 1 | G23: 20 | H23: 20 | M23: 570000 | AA23: DHL | AB23: =A23 -> PS260814 | AC23: =B23 -> IV260103194 | AD23: =D23 -> 46055 | AE23: =G23/H23*J23 -> 0 | AF23: =(G23/H23)*K23 -> 0 | AG23: =(G23/H23)*L23 -> 0 | AH23: =(G23/H23)*M23 -> 570000 | AI23: =(G23/H23)*N23 -> 0 | AJ23: =(G23/H23)*O23 -> 0 | AK23: =(G23/H23)*P23 -> 0 | AL23: =(G23/H23)*Q23 -> 0 | AM23: =(G23/H23)*R23 -> 0 | AN23: =(G23/H23)*S23 -> 0 | AO23: =(G23/H23)*T23 -> 0 | AP23: =(G23/H23)*U23 -> 0 | AQ23: =(G23/H23)*V23 -> 0 | AR23: =SUM(AG23:AQ23)*0.08 -> 45600 | AS23: =SUM(AG23:AR23) -> 615600 | AT23: =AS23 -> 615600 | AU23: =AA23 -> DHL | AV23: EXP | AW23: ADCDNB-26.02-000451
A24: PS260805 | B24: IV260102980 | C24: 5162398905 | D24: 46055 | E24: 107951960100 | F24: 1 | G24: 1.5 | H24: 1.5 | M24: 570000 | AA24: DHL | AB24: =A24 -> PS260805 | AC24: =B24 -> IV260102980 | AD24: =D24 -> 46055 | AE24: =G24/H24*J24 -> 0 | AF24: =(G24/H24)*K24 -> 0 | AG24: =(G24/H24)*L24 -> 0 | AH24: =(G24/H24)*M24 -> 570000 | AI24: =(G24/H24)*N24 -> 0 | AJ24: =(G24/H24)*O24 -> 0 | AK24: =(G24/H24)*P24 -> 0 | AL24: =(G24/H24)*Q24 -> 0 | AM24: =(G24/H24)*R24 -> 0 | AN24: =(G24/H24)*S24 -> 0 | AO24: =(G24/H24)*T24 -> 0 | AP24: =(G24/H24)*U24 -> 0 | AQ24: =(G24/H24)*V24 -> 0 | AR24: =SUM(AG24:AQ24)*0.08 -> 45600 | AS24: =SUM(AG24:AR24) -> 615600 | AT24: =AS24 -> 615600 | AU24: =AA24 -> DHL | AV24: EXP | AW24: ADCDNB-26.02-000452
A25: PS260804 | B25: PS26-804 | C25: 5162376693 | D25: 46055 | E25: 107952014220 | F25: 1 | G25: 7.1 | H25: 7.1 | M25: 570000 | AA25: DHL | AB25: =A25 -> PS260804 | AC25: =B25 -> PS26-804 | AD25: =D25 -> 46055 | AE25: =G25/H25*J25 -> 0 | AF25: =(G25/H25)*K25 -> 0 | AG25: =(G25/H25)*L25 -> 0 | AH25: =(G25/H25)*M25 -> 570000 | AI25: =(G25/H25)*N25 -> 0 | AJ25: =(G25/H25)*O25 -> 0 | AK25: =(G25/H25)*P25 -> 0 | AL25: =(G25/H25)*Q25 -> 0 | AM25: =(G25/H25)*R25 -> 0 | AN25: =(G25/H25)*S25 -> 0 | AO25: =(G25/H25)*T25 -> 0 | AP25: =(G25/H25)*U25 -> 0 | AQ25: =(G25/H25)*V25 -> 0 | AR25: =SUM(AG25:AQ25)*0.08 -> 45600 | AS25: =SUM(AG25:AR25) -> 615600 | AT25: =AS25 -> 615600 | AU25: =AA25 -> DHL | AV25: EXP | AW25: ADCDNB-26.02-000453
A26: PS260803 | B26: 00013-00131393 | C26: 5496713843 | D26: 46056 | E26: 107953077740 | F26: 1 | G26: 2.5 | H26: 2.5 | M26: 570000 | AA26: DHL | AB26: =A26 -> PS260803 | AC26: =B26 -> 00013-00131393 | AD26: =D26 -> 46056 | AE26: =G26/H26*J26 -> 0 | AF26: =(G26/H26)*K26 -> 0 | AG26: =(G26/H26)*L26 -> 0 | AH26: =(G26/H26)*M26 -> 570000 | AI26: =(G26/H26)*N26 -> 0 | AJ26: =(G26/H26)*O26 -> 0 | AK26: =(G26/H26)*P26 -> 0 | AL26: =(G26/H26)*Q26 -> 0 | AM26: =(G26/H26)*R26 -> 0 | AN26: =(G26/H26)*S26 -> 0 | AO26: =(G26/H26)*T26 -> 0 | AP26: =(G26/H26)*U26 -> 0 | AQ26: =(G26/H26)*V26 -> 0 | AR26: =SUM(AG26:AQ26)*0.08 -> 45600 | AS26: =SUM(AG26:AR26) -> 615600 | AT26: =AS26 -> 615600 | AU26: =AA26 -> DHL | AV26: EXP | AW26: ADCDNB-26.02-000454
A27: PS260833 | B27: ZS26013001 | C27: 3405477342 | D27: 46056 | E27: 107954071410 | F27: 1 | G27: 4.5 | H27: 4.5 | M27: 570000 | AA27: DHL | AB27: =A27 -> PS260833 | AC27: =B27 -> ZS26013001 | AD27: =D27 -> 46056 | AE27: =G27/H27*J27 -> 0 | AF27: =(G27/H27)*K27 -> 0 | AG27: =(G27/H27)*L27 -> 0 | AH27: =(G27/H27)*M27 -> 570000 | AI27: =(G27/H27)*N27 -> 0 | AJ27: =(G27/H27)*O27 -> 0 | AK27: =(G27/H27)*P27 -> 0 | AL27: =(G27/H27)*Q27 -> 0 | AM27: =(G27/H27)*R27 -> 0 | AN27: =(G27/H27)*S27 -> 0 | AO27: =(G27/H27)*T27 -> 0 | AP27: =(G27/H27)*U27 -> 0 | AQ27: =(G27/H27)*V27 -> 0 | AR27: =SUM(AG27:AQ27)*0.08 -> 45600 | AS27: =SUM(AG27:AR27) -> 615600 | AT27: =AS27 -> 615600 | AU27: =AA27 -> DHL | AV27: EXP | AW27: ADCDNB-26.02-000455
A28: PS260807 | B28: 2/PQR-PS/26 | C28: 112600036867319 | D28: 46056 | E28: 107951650920 | F28: 1 | G28: 218 | H28: 218 | L28: {=IF(H28=0, _xleta.T, IF(H28<=1000, 1790000, IF(H28<=2000, 1960000, IF(H28<=3000, 2686000, IF(H28<=5000, 2796000, ff)))))} -> 1790000 | M28: 940500 | Z28: 50H69350 | AA28: HIỆP PHƯỚC | AB28: =A28 -> PS260807 | AC28: =B28 -> 2/PQR-PS/26 | AD28: =D28 -> 46056 | AE28: =G28/H28*J28 -> 0 | AF28: =(G28/H28)*K28 -> 0 | AG28: =(G28/H28)*L28 -> 1790000 | AH28: =(G28/H28)*M28 -> 940500 | AI28: =(G28/H28)*N28 -> 0 | AJ28: =(G28/H28)*O28 -> 0 | AK28: =(G28/H28)*P28 -> 0 | AL28: =(G28/H28)*Q28 -> 0 | AM28: =(G28/H28)*R28 -> 0 | AN28: =(G28/H28)*S28 -> 0 | AO28: =(G28/H28)*T28 -> 0 | AP28: =(G28/H28)*U28 -> 0 | AQ28: =(G28/H28)*V28 -> 0 | AR28: =SUM(AG28:AQ28)*0.08 -> 218440 | AS28: =SUM(AG28:AR28) -> 2948940 | AT28: =AS28 -> 2948940 | AU28: =AA28 -> HIỆP PHƯỚC | AV28: LCL | AW28: ADCDNB-26.02-000456 | AX28: , từ Cảng Hiệp Phước đến KCN Bàu Xéo, Đồng Nai | AY28: 46057 | AZ28: 50H69350 | BA28: 1 X 1MT
